Workbook

Sheet OUT_1
A1: In | B1: =SUMIFS(Cash_Flow_3[Amount],Cash_Flow_3[Type],"In",Cash_Flow_3[Category],"Fix")-SUMIFS(Cash_Flow_3[Amount],Cash_Flow_3[Type],"Out",Cash_Flow_3[Category],"Move") -> 11528011 | D1: ATM | E1: =SUMIFS(Cash_Flow_3[Amount],Cash_Flow_3[ATM/Cash],"ATM",Cash_Flow_3[Type],"In") -SUMIFS(Cash_Flow_3[Amount],Cash_Flow_3[ATM/Cash],"ATM",Cash_Flow_3[Type],"Out") -SUMIFS(Cash_Flow_3[Amount],Cash_Flow_3[ATM/Cash],"ATM",Cash_Flow_3[Type],"Move") -> 1228691 | H1: -SUMMARY-
A2: Out | B2: =SUMIFS(Cash_Flow_3[Amount],Cash_Flow_3[Type],"Out",Cash_Flow_3[Category],"<>Move") -> 11407430 | D2: Cash | E2: =SUMIFS(Cash_Flow_3[Amount],Cash_Flow_3[ATM/Cash],"Cash",Cash_Flow_3[Type],"In") -SUMIFS(Cash_Flow_3[Amount],Cash_Flow_3[ATM/Cash],"Cash",Cash_Flow_3[Type],"Out") +SUMIFS(Cash_Flow_3[Amount],Cash_Flow_3[ATM/Cash],"Cash",Cash_Flow_3[Type],"Move") -> 96700
D3: ATM + Cash | E3: =SUM(E1:F2) -> 1325391
A4: Date | B4: Description | C4: ATM/Cash | D4: Type | E4: Category | F4: Amount | G4: Column 10 | H4: Bulan | I4: In | J4: Out | K4: Fix | L4: Bathroom | M4: Alfa | N4: Jajan | O4: Kitchen | P4: Loandry | Q4: Mio | R4: Sedekah | S4: Zela | T4: Iqbal
A5: 46050 | B5: Saldo Awal | C5: ATM | D5: In | E5: Fix | F5: 15590 | H5: =IF(A5="","", DATE(YEAR(A5),MONTH(A5),1) ) -> 46023 | I5: =SUMIFS(Cash_Flow_3[Amount],Cash_Flow_3[Bulan],H5,Cash_Flow_3[Type],"In") -> 543327 | J5: =SUMIFS(Cash_Flow_3[Amount],Cash_Flow_3[Bulan],H5,Cash_Flow_3[Type],"Out") -> 475850 | K5: =SUMIFS(Cash_Flow_3[Amount],Cash_Flow_3[Bulan],H5,Cash_Flow_3[Type],"Out",Cash_Flow_3[Category],"Fix") -> 114450 | L5: =SUMIFS(Cash_Flow_3[Amount],Cash_Flow_3[Bulan],H5,Cash_Flow_3[Type],"Out",Cash_Flow_3[Category],"Bathroom") -> 0 | M5: =SUMIFS(Cash_Flow_3[Amount],Cash_Flow_3[Bulan],H5,Cash_Flow_3[Type],"Out",Cash_Flow_3[Category],"Alfa") -> 36400 | N5: =SUMIFS(Cash_Flow_3[Amount],Cash_Flow_3[Bulan],H5,Cash_Flow_3[Type],"Out",Cash_Flow_3[Category],"Jajan") -> 38000 | O5: =SUMIFS(Cash_Flow_3[Amount],Cash_Flow_3[Bulan],H5,Cash_Flow_3[Type],"Out",Cash_Flow_3[Category],"Kitchen") -> 87000 | P5: =SUMIFS(Cash_Flow_3[Amount],Cash_Flow_3[Bulan],H5,Cash_Flow_3[Type],"Out",Cash_Flow_3[Category],"Loandry") -> 0 | Q5: =SUMIFS(Cash_Flow_3[Amount],Cash_Flow_3[Bulan],H5,Cash_Flow_3[Type],"Out",Cash_Flow_3[Category],"Mio") -> 0 | R5: =SUMIFS(Cash_Flow_3[Amount],Cash_Flow_3[Bulan],H5,Cash_Flow_3[Type],"Out",Cash_Flow_3[Category],"Sedekah") -> 0 | S5: =SUMIFS(Cash_Flow_3[Amount],Cash_Flow_3[Bulan],H5,Cash_Flow_3[Type],"Out",Cash_Flow_3[Category],"Zela") -> 0 | T5: =SUMIFS(Cash_Flow_3[Amount],Cash_Flow_3[Bulan],H5,Cash_Flow_3[Type],"Out",Cash_Flow_3[Category],"Iqbal") -> 0
A6: 46051 | B6: Pinjam uang Adi | C6: ATM | D6: In | E6: Fix | F6: 300000 | H6: =IF(A6="","", DATE(YEAR(A6),MONTH(A6),1) ) -> 46023 | I6: =SUMIFS(Cash_Flow_3[Amount],Cash_Flow_3[Bulan],H6,Cash_Flow_3[Type],"In") -> 543327 | J6: =SUMIFS(Cash_Flow_3[Amount],Cash_Flow_3[Bulan],H6,Cash_Flow_3[Type],"Out") -> 475850 | K6: =SUMIFS(Cash_Flow_3[Amount],Cash_Flow_3[Bulan],H6,Cash_Flow_3[Type],"Out",Cash_Flow_3[Category],"Fix") -> 114450 | L6: =SUMIFS(Cash_Flow_3[Amount],Cash_Flow_3[Bulan],H6,Cash_Flow_3[Type],"Out",Cash_Flow_3[Category],"Bathroom") -> 0 | M6: =SUMIFS(Cash_Flow_3[Amount],Cash_Flow_3[Bulan],H6,Cash_Flow_3[Type],"Out",Cash_Flow_3[Category],"Alfa") -> 36400 | N6: =SUMIFS(Cash_Flow_3[Amount],Cash_Flow_3[Bulan],H6,Cash_Flow_3[Type],"Out",Cash_Flow_3[Category],"Jajan") -> 38000 | O6: =SUMIFS(Cash_Flow_3[Amount],Cash_Flow_3[Bulan],H6,Cash_Flow_3[Type],"Out",Cash_Flow_3[Category],"Kitchen") -> 87000 | P6: =SUMIFS(Cash_Flow_3[Amount],Cash_Flow_3[Bulan],H6,Cash_Flow_3[Type],"Out",Cash_Flow_3[Category],"Loandry") -> 0 | Q6: =SUMIFS(Cash_Flow_3[Amount],Cash_Flow_3[Bulan],H6,Cash_Flow_3[Type],"Out",Cash_Flow_3[Category],"Mio") -> 0 | R6: =SUMIFS(Cash_Flow_3[Amount],Cash_Flow_3[Bulan],H6,Cash_Flow_3[Type],"Out",Cash_Flow_3[Category],"Sedekah") -> 0 | S6: =SUMIFS(Cash_Flow_3[Amount],Cash_Flow_3[Bulan],H6,Cash_Flow_3[Type],"Out",Cash_Flow_3[Category],"Zela") -> 0 | T6: =SUMIFS(Cash_Flow_3[Amount],Cash_Flow_3[Bulan],H6,Cash_Flow_3[Type],"Out",Cash_Flow_3[Category],"Iqbal") -> 0
A7: 46051 | B7: Istriku | C7: ATM | D7: Out | E7: Move | F7: 150000 | H7: =IF(A7="","", DATE(YEAR(A7),MONTH(A7),1) ) -> 46023 | I7: =SUMIFS(Cash_Flow_3[Amount],Cash_Flow_3[Bulan],H7,Cash_Flow_3[Type],"In") -> 543327 | J7: =SUMIFS(Cash_Flow_3[Amount],Cash_Flow_3[Bulan],H7,Cash_Flow_3[Type],"Out") -> 475850 | K7: =SUMIFS(Cash_Flow_3[Amount],Cash_Flow_3[Bulan],H7,Cash_Flow_3[Type],"Out",Cash_Flow_3[Category],"Fix") -> 114450 | L7: =SUMIFS(Cash_Flow_3[Amount],Cash_Flow_3[Bulan],H7,Cash_Flow_3[Type],"Out",Cash_Flow_3[Category],"Bathroom") -> 0 | M7: =SUMIFS(Cash_Flow_3[Amount],Cash_Flow_3[Bulan],H7,Cash_Flow_3[Type],"Out",Cash_Flow_3[Category],"Alfa") -> 36400 | N7: =SUMIFS(Cash_Flow_3[Amount],Cash_Flow_3[Bulan],H7,Cash_Flow_3[Type],"Out",Cash_Flow_3[Category],"Jajan") -> 38000 | O7: =SUMIFS(Cash_Flow_3[Amount],Cash_Flow_3[Bulan],H7,Cash_Flow_3[Type],"Out",Cash_Flow_3[Category],"Kitchen") -> 87000 | P7: =SUMIFS(Cash_Flow_3[Amount],Cash_Flow_3[Bulan],H7,Cash_Flow_3[Type],"Out",Cash_Flow_3[Category],"Loandry") -> 0 | Q7: =SUMIFS(Cash_Flow_3[Amount],Cash_Flow_3[Bulan],H7,Cash_Flow_3[Type],"Out",Cash_Flow_3[Category],"Mio") -> 0 | R7: =SUMIFS(Cash_Flow_3[Amount],Cash_Flow_3[Bulan],H7,Cash_Flow_3[Type],"Out",Cash_Flow_3[Category],"Sedekah") -> 0 | S7: =SUMIFS(Cash_Flow_3[Amount],Cash_Flow_3[Bulan],H7,Cash_Flow_3[Type],"Out",Cash_Flow_3[Category],"Zela") -> 0 | T7: =SUMIFS(Cash_Flow_3[Amount],Cash_Flow_3[Bulan],H7,Cash_Flow_3[Type],"Out",Cash_Flow_3[Category],"Iqbal") -> 0
A8: 46051 | B8: Token listrik 100k (65,30 kwh) | C8: ATM | D8: Out | E8: Fix | F8: 99450 | H8: =IF(A8="","", DATE(YEAR(A8),MONTH(A8),1) ) -> 46023 | I8: =SUMIFS(Cash_Flow_3[Amount],Cash_Flow_3[Bulan],H8,Cash_Flow_3[Type],"In") -> 543327 | J8: =SUMIFS(Cash_Flow_3[Amount],Cash_Flow_3[Bulan],H8,Cash_Flow_3[Type],"Out") -> 475850 | K8: =SUMIFS(Cash_Flow_3[Amount],Cash_Flow_3[Bulan],H8,Cash_Flow_3[Type],"Out",Cash_Flow_3[Category],"Fix") -> 114450 | L8: =SUMIFS(Cash_Flow_3[Amount],Cash_Flow_3[Bulan],H8,Cash_Flow_3[Type],"Out",Cash_Flow_3[Category],"Bathroom") -> 0 | M8: =SUMIFS(Cash_Flow_3[Amount],Cash_Flow_3[Bulan],H8,Cash_Flow_3[Type],"Out",Cash_Flow_3[Category],"Alfa") -> 36400 | N8: =SUMIFS(Cash_Flow_3[Amount],Cash_Flow_3[Bulan],H8,Cash_Flow_3[Type],"Out",Cash_Flow_3[Category],"Jajan") -> 38000 | O8: =SUMIFS(Cash_Flow_3[Amount],Cash_Flow_3[Bulan],H8,Cash_Flow_3[Type],"Out",Cash_Flow_3[Category],"Kitchen") -> 87000 | P8: =SUMIFS(Cash_Flow_3[Amount],Cash_Flow_3[Bulan],H8,Cash_Flow_3[Type],"Out",Cash_Flow_3[Category],"Loandry") -> 0 | Q8: =SUMIFS(Cash_Flow_3[Amount],Cash_Flow_3[Bulan],H8,Cash_Flow_3[Type],"Out",Cash_Flow_3[Category],"Mio") -> 0 | R8: =SUMIFS(Cash_Flow_3[Amount],Cash_Flow_3[Bulan],H8,Cash_Flow_3[Type],"Out",Cash_Flow_3[Category],"Sedekah") -> 0 | S8: =SUMIFS(Cash_Flow_3[Amount],Cash_Flow_3[Bulan],H8,Cash_Flow_3[Type],"Out",Cash_Flow_3[Category],"Zela") -> 0 | T8: =SUMIFS(Cash_Flow_3[Amount],Cash_Flow_3[Bulan],H8,Cash_Flow_3[Type],"Out",Cash_Flow_3[Category],"Iqbal") -> 0
A9: 46052 | B9: Istriku | C9: ATM | D9: Out | E9: Move | F9: 50000 | H9: =IF(A9="","", DATE(YEAR(A9),MONTH(A9),1) ) -> 46023 | I9: =SUMIFS(Cash_Flow_3[Amount],Cash_Flow_3[Bulan],H9,Cash_Flow_3[Type],"In") -> 543327 | J9: =SUMIFS(Cash_Flow_3[Amount],Cash_Flow_3[Bulan],H9,Cash_Flow_3[Type],"Out") -> 475850 | K9: =SUMIFS(Cash_Flow_3[Amount],Cash_Flow_3[Bulan],H9,Cash_Flow_3[Type],"Out",Cash_Flow_3[Category],"Fix") -> 114450 | L9: =SUMIFS(Cash_Flow_3[Amount],Cash_Flow_3[Bulan],H9,Cash_Flow_3[Type],"Out",Cash_Flow_3[Category],"Bathroom") -> 0 | M9: =SUMIFS(Cash_Flow_3[Amount],Cash_Flow_3[Bulan],H9,Cash_Flow_3[Type],"Out",Cash_Flow_3[Category],"Alfa") -> 36400 | N9: =SUMIFS(Cash_Flow_3[Amount],Cash_Flow_3[Bulan],H9,Cash_Flow_3[Type],"Out",Cash_Flow_3[Category],"Jajan") -> 38000 | O9: =SUMIFS(Cash_Flow_3[Amount],Cash_Flow_3[Bulan],H9,Cash_Flow_3[Type],"Out",Cash_Flow_3[Category],"Kitchen") -> 87000 | P9: =SUMIFS(Cash_Flow_3[Amount],Cash_Flow_3[Bulan],H9,Cash_Flow_3[Type],"Out",Cash_Flow_3[Category],"Loandry") -> 0 | Q9: =SUMIFS(Cash_Flow_3[Amount],Cash_Flow_3[Bulan],H9,Cash_Flow_3[Type],"Out",Cash_Flow_3[Category],"Mio") -> 0 | R9: =SUMIFS(Cash_Flow_3[Amount],Cash_Flow_3[Bulan],H9,Cash_Flow_3[Type],"Out",Cash_Flow_3[Category],"Sedekah") -> 0 | S9: =SUMIFS(Cash_Flow_3[Amount],Cash_Flow_3[Bulan],H9,Cash_Flow_3[Type],"Out",Cash_Flow_3[Category],"Zela") -> 0 | T9: =SUMIFS(Cash_Flow_3[Amount],Cash_Flow_3[Bulan],H9,Cash_Flow_3[Type],"Out",Cash_Flow_3[Category],"Iqbal") -> 0
A10: 46055 | B10: Gaji Januari 2026 | C10: ATM | D10: In | E10: Fix | F10: 4353235 | H10: =IF(A10="","", DATE(YEAR(A10),MONTH(A10),1) ) -> 46054 | I10: =SUMIFS(Cash_Flow_3[Amount],Cash_Flow_3[Bulan],H10,Cash_Flow_3[Type],"In") -> 7073728 | J10: =SUMIFS(Cash_Flow_3[Amount],Cash_Flow_3[Bulan],H10,Cash_Flow_3[Type],"Out") -> 6908733 | K10: =SUMIFS(Cash_Flow_3[Amount],Cash_Flow_3[Bulan],H10,Cash_Flow_3[Type],"Out",Cash_Flow_3[Category],"Fix") -> 2440568 | L10: =SUMIFS(Cash_Flow_3[Amount],Cash_Flow_3[Bulan],H10,Cash_Flow_3[Type],"Out",Cash_Flow_3[Category],"Bathroom") -> 34500 | M10: =SUMIFS(Cash_Flow_3[Amount],Cash_Flow_3[Bulan],H10,Cash_Flow_3[Type],"Out",Cash_Flow_3[Category],"Alfa") -> 293800 | N10: =SUMIFS(Cash_Flow_3[Amount],Cash_Flow_3[Bulan],H10,Cash_Flow_3[Type],"Out",Cash_Flow_3[Category],"Jajan") -> 364000 | O10: =SUMIFS(Cash_Flow_3[Amount],Cash_Flow_3[Bulan],H10,Cash_Flow_3[Type],"Out",Cash_Flow_3[Category],"Kitchen") -> 992724 | P10: =SUMIFS(Cash_Flow_3[Amount],Cash_Flow_3[Bulan],H10,Cash_Flow_3[Type],"Out",Cash_Flow_3[Category],"Loandry") -> 41600 | Q10: =SUMIFS(Cash_Flow_3[Amount],Cash_Flow_3[Bulan],H10,Cash_Flow_3[Type],"Out",Cash_Flow_3[Category],"Mio") -> 249000 | R10: =SUMIFS(Cash_Flow_3[Amount],Cash_Flow_3[Bulan],H10,Cash_Flow_3[Type],"Out",Cash_Flow_3[Category],"Sedekah") -> 129000 | S10: =SUMIFS(Cash_Flow_3[Amount],Cash_Flow_3[Bulan],H10,Cash_Flow_3[Type],"Out",Cash_Flow_3[Category],"Zela") -> 24100 | T10: =SUMIFS(Cash_Flow_3[Amount],Cash_Flow_3[Bulan],H10,Cash_Flow_3[Type],"Out",Cash_Flow_3[Category],"Iqbal") -> 121000
A11: 46055 | B11: Byu 10GB | C11: ATM | D11: Out | E11: Fix | F11: 25000 | H11: =IF(A11="","", DATE(YEAR(A11),MONTH(A11),1) ) -> 46054 | I11: =SUMIFS(Cash_Flow_3[Amount],Cash_Flow_3[Bulan],H11,Cash_Flow_3[Type],"In") -> 7073728 | J11: =SUMIFS(Cash_Flow_3[Amount],Cash_Flow_3[Bulan],H11,Cash_Flow_3[Type],"Out") -> 6908733 | K11: =SUMIFS(Cash_Flow_3[Amount],Cash_Flow_3[Bulan],H11,Cash_Flow_3[Type],"Out",Cash_Flow_3[Category],"Fix") -> 2440568 | L11: =SUMIFS(Cash_Flow_3[Amount],Cash_Flow_3[Bulan],H11,Cash_Flow_3[Type],"Out",Cash_Flow_3[Category],"Bathroom") -> 34500 | M11: =SUMIFS(Cash_Flow_3[Amount],Cash_Flow_3[Bulan],H11,Cash_Flow_3[Type],"Out",Cash_Flow_3[Category],"Alfa") -> 293800 | N11: =SUMIFS(Cash_Flow_3[Amount],Cash_Flow_3[Bulan],H11,Cash_Flow_3[Type],"Out",Cash_Flow_3[Category],"Jajan") -> 364000 | O11: =SUMIFS(Cash_Flow_3[Amount],Cash_Flow_3[Bulan],H11,Cash_Flow_3[Type],"Out",Cash_Flow_3[Category],"Kitchen") -> 992724 | P11: =SUMIFS(Cash_Flow_3[Amount],Cash_Flow_3[Bulan],H11,Cash_Flow_3[Type],"Out",Cash_Flow_3[Category],"Loandry") -> 41600 | Q11: =SUMIFS(Cash_Flow_3[Amount],Cash_Flow_3[Bulan],H11,Cash_Flow_3[Type],"Out",Cash_Flow_3[Category],"Mio") -> 249000 | R11: =SUMIFS(Cash_Flow_3[Amount],Cash_Flow_3[Bulan],H11,Cash_Flow_3[Type],"Out",Cash_Flow_3[Category],"Sedekah") -> 129000 | S11: =SUMIFS(Cash_Flow_3[Amount],Cash_Flow_3[Bulan],H11,Cash_Flow_3[Type],"Out",Cash_Flow_3[Category],"Zela") -> 24100 | T11: =SUMIFS(Cash_Flow_3[Amount],Cash_Flow_3[Bulan],H11,Cash_Flow_3[Type],"Out",Cash_Flow_3[Category],"Iqbal") -> 121000
A12: 46055 | B12: Istriku | C12: ATM | D12: Out | E12: Move | F12: 1774441 | H12: =IF(A12="","", DATE(YEAR(A12),MONTH(A12),1) ) -> 46054 | I12: =SUMIFS(Cash_Flow_3[Amount],Cash_Flow_3[Bulan],H12,Cash_Flow_3[Type],"In") -> 7073728 | J12: =SUMIFS(Cash_Flow_3[Amount],Cash_Flow_3[Bulan],H12,Cash_Flow_3[Type],"Out") -> 6908733 | K12: =SUMIFS(Cash_Flow_3[Amount],Cash_Flow_3[Bulan],H12,Cash_Flow_3[Type],"Out",Cash_Flow_3[Category],"Fix") -> 2440568 | L12: =SUMIFS(Cash_Flow_3[Amount],Cash_Flow_3[Bulan],H12,Cash_Flow_3[Type],"Out",Cash_Flow_3[Category],"Bathroom") -> 34500 | M12: =SUMIFS(Cash_Flow_3[Amount],Cash_Flow_3[Bulan],H12,Cash_Flow_3[Type],"Out",Cash_Flow_3[Category],"Alfa") -> 293800 | N12: =SUMIFS(Cash_Flow_3[Amount],Cash_Flow_3[Bulan],H12,Cash_Flow_3[Type],"Out",Cash_Flow_3[Category],"Jajan") -> 364000 | O12: =SUMIFS(Cash_Flow_3[Amount],Cash_Flow_3[Bulan],H12,Cash_Flow_3[Type],"Out",Cash_Flow_3[Category],"Kitchen") -> 992724 | P12: =SUMIFS(Cash_Flow_3[Amount],Cash_Flow_3[Bulan],H12,Cash_Flow_3[Type],"Out",Cash_Flow_3[Category],"Loandry") -> 41600 | Q12: =SUMIFS(Cash_Flow_3[Amount],Cash_Flow_3[Bulan],H12,Cash_Flow_3[Type],"Out",Cash_Flow_3[Category],"Mio") -> 249000 | R12: =SUMIFS(Cash_Flow_3[Amount],Cash_Flow_3[Bulan],H12,Cash_Flow_3[Type],"Out",Cash_Flow_3[Category],"Sedekah") -> 129000 | S12: =SUMIFS(Cash_Flow_3[Amount],Cash_Flow_3[Bulan],H12,Cash_Flow_3[Type],"Out",Cash_Flow_3[Category],"Zela") -> 24100 | T12: =SUMIFS(Cash_Flow_3[Amount],Cash_Flow_3[Bulan],H12,Cash_Flow_3[Type],"Out",Cash_Flow_3[Category],"Iqbal") -> 121000
A13: 46055 | B13: Bayar uang Adi | C13: ATM | D13: Out | E13: Fix | F13: 300000 | H13: =IF(A13="","", DATE(YEAR(A13),MONTH(A13),1) ) -> 46054 | I13: =SUMIFS(Cash_Flow_3[Amount],Cash_Flow_3[Bulan],H13,Cash_Flow_3[Type],"In") -> 7073728 | J13: =SUMIFS(Cash_Flow_3[Amount],Cash_Flow_3[Bulan],H13,Cash_Flow_3[Type],"Out") -> 6908733 | K13: =SUMIFS(Cash_Flow_3[Amount],Cash_Flow_3[Bulan],H13,Cash_Flow_3[Type],"Out",Cash_Flow_3[Category],"Fix") -> 2440568 | L13: =SUMIFS(Cash_Flow_3[Amount],Cash_Flow_3[Bulan],H13,Cash_Flow_3[Type],"Out",Cash_Flow_3[Category],"Bathroom") -> 34500 | M13: =SUMIFS(Cash_Flow_3[Amount],Cash_Flow_3[Bulan],H13,Cash_Flow_3[Type],"Out",Cash_Flow_3[Category],"Alfa") -> 293800 | N13: =SUMIFS(Cash_Flow_3[Amount],Cash_Flow_3[Bulan],H13,Cash_Flow_3[Type],"Out",Cash_Flow_3[Category],"Jajan") -> 364000 | O13: =SUMIFS(Cash_Flow_3[Amount],Cash_Flow_3[Bulan],H13,Cash_Flow_3[Type],"Out",Cash_Flow_3[Category],"Kitchen") -> 992724 | P13: =SUMIFS(Cash_Flow_3[Amount],Cash_Flow_3[Bulan],H13,Cash_Flow_3[Type],"Out",Cash_Flow_3[Category],"Loandry") -> 41600 | Q13: =SUMIFS(Cash_Flow_3[Amount],Cash_Flow_3[Bulan],H13,Cash_Flow_3[Type],"Out",Cash_Flow_3[Category],"Mio") -> 249000 | R13: =SUMIFS(Cash_Flow_3[Amount],Cash_Flow_3[Bulan],H13,Cash_Flow_3[Type],"Out",Cash_Flow_3[Category],"Sedekah") -> 129000 | S13: =SUMIFS(Cash_Flow_3[Amount],Cash_Flow_3[Bulan],H13,Cash_Flow_3[Type],"Out",Cash_Flow_3[Category],"Zela") -> 24100 | T13: =SUMIFS(Cash_Flow_3[Amount],Cash_Flow_3[Bulan],H13,Cash_Flow_3[Type],"Out",Cash_Flow_3[Category],"Iqbal") -> 121000
A14: 46055 | B14: Iqbal Shopee (5) | C14: ATM | D14: Out | E14: Fix | F14: 624137 | H14: =IF(A14="","", DATE(YEAR(A14),MONTH(A14),1) ) -> 46054 | I14: =SUMIFS(Cash_Flow_3[Amount],Cash_Flow_3[Bulan],H14,Cash_Flow_3[Type],"In") -> 7073728 | J14: =SUMIFS(Cash_Flow_3[Amount],Cash_Flow_3[Bulan],H14,Cash_Flow_3[Type],"Out") -> 6908733 | K14: =SUMIFS(Cash_Flow_3[Amount],Cash_Flow_3[Bulan],H14,Cash_Flow_3[Type],"Out",Cash_Flow_3[Category],"Fix") -> 2440568 | L14: =SUMIFS(Cash_Flow_3[Amount],Cash_Flow_3[Bulan],H14,Cash_Flow_3[Type],"Out",Cash_Flow_3[Category],"Bathroom") -> 34500 | M14: =SUMIFS(Cash_Flow_3[Amount],Cash_Flow_3[Bulan],H14,Cash_Flow_3[Type],"Out",Cash_Flow_3[Category],"Alfa") -> 293800 | N14: =SUMIFS(Cash_Flow_3[Amount],Cash_Flow_3[Bulan],H14,Cash_Flow_3[Type],"Out",Cash_Flow_3[Category],"Jajan") -> 364000 | O14: =SUMIFS(Cash_Flow_3[Amount],Cash_Flow_3[Bulan],H14,Cash_Flow_3[Type],"Out",Cash_Flow_3[Category],"Kitchen") -> 992724 | P14: =SUMIFS(Cash_Flow_3[Amount],Cash_Flow_3[Bulan],H14,Cash_Flow_3[Type],"Out",Cash_Flow_3[Category],"Loandry") -> 41600 | Q14: =SUMIFS(Cash_Flow_3[Amount],Cash_Flow_3[Bulan],H14,Cash_Flow_3[Type],"Out",Cash_Flow_3[Category],"Mio") -> 249000 | R14: =SUMIFS(Cash_Flow_3[Amount],Cash_Flow_3[Bulan],H14,Cash_Flow_3[Type],"Out",Cash_Flow_3[Category],"Sedekah") -> 129000 | S14: =SUMIFS(Cash_Flow_3[Amount],Cash_Flow_3[Bulan],H14,Cash_Flow_3[Type],"Out",Cash_Flow_3[Category],"Zela") -> 24100 | T14: =SUMIFS(Cash_Flow_3[Amount],Cash_Flow_3[Bulan],H14,Cash_Flow_3[Type],"Out",Cash_Flow_3[Category],"Iqbal") -> 121000
A15: 46055 | B15: Kulkas (2) | C15: ATM | D15: Out | E15: Fix | F15: 279187 | H15: =IF(A15="","", DATE(YEAR(A15),MONTH(A15),1) ) -> 46054 | I15: =SUMIFS(Cash_Flow_3[Amount],Cash_Flow_3[Bulan],H15,Cash_Flow_3[Type],"In") -> 7073728 | J15: =SUMIFS(Cash_Flow_3[Amount],Cash_Flow_3[Bulan],H15,Cash_Flow_3[Type],"Out") -> 6908733 | K15: =SUMIFS(Cash_Flow_3[Amount],Cash_Flow_3[Bulan],H15,Cash_Flow_3[Type],"Out",Cash_Flow_3[Category],"Fix") -> 2440568 | L15: =SUMIFS(Cash_Flow_3[Amount],Cash_Flow_3[Bulan],H15,Cash_Flow_3[Type],"Out",Cash_Flow_3[Category],"Bathroom") -> 34500 | M15: =SUMIFS(Cash_Flow_3[Amount],Cash_Flow_3[Bulan],H15,Cash_Flow_3[Type],"Out",Cash_Flow_3[Category],"Alfa") -> 293800 | N15: =SUMIFS(Cash_Flow_3[Amount],Cash_Flow_3[Bulan],H15,Cash_Flow_3[Type],"Out",Cash_Flow_3[Category],"Jajan") -> 364000 | O15: =SUMIFS(Cash_Flow_3[Amount],Cash_Flow_3[Bulan],H15,Cash_Flow_3[Type],"Out",Cash_Flow_3[Category],"Kitchen") -> 992724 | P15: =SUMIFS(Cash_Flow_3[Amount],Cash_Flow_3[Bulan],H15,Cash_Flow_3[Type],"Out",Cash_Flow_3[Category],"Loandry") -> 41600 | Q15: =SUMIFS(Cash_Flow_3[Amount],Cash_Flow_3[Bulan],H15,Cash_Flow_3[Type],"Out",Cash_Flow_3[Category],"Mio") -> 249000 | R15: =SUMIFS(Cash_Flow_3[Amount],Cash_Flow_3[Bulan],H15,Cash_Flow_3[Type],"Out",Cash_Flow_3[Category],"Sedekah") -> 129000 | S15: =SUMIFS(Cash_Flow_3[Amount],Cash_Flow_3[Bulan],H15,Cash_Flow_3[Type],"Out",Cash_Flow_3[Category],"Zela") -> 24100 | T15: =SUMIFS(Cash_Flow_3[Amount],Cash_Flow_3[Bulan],H15,Cash_Flow_3[Type],"Out",Cash_Flow_3[Category],"Iqbal") -> 121000
A16: 46056 | B16: Potong rambut | C16: ATM | D16: Out | E16: Iqbal | F16: 30000 | H16: =IF(A16="","", DATE(YEAR(A16),MONTH(A16),1) ) -> 46054 | I16: =SUMIFS(Cash_Flow_3[Amount],Cash_Flow_3[Bulan],H16,Cash_Flow_3[Type],"In") -> 7073728 | J16: =SUMIFS(Cash_Flow_3[Amount],Cash_Flow_3[Bulan],H16,Cash_Flow_3[Type],"Out") -> 6908733 | K16: =SUMIFS(Cash_Flow_3[Amount],Cash_Flow_3[Bulan],H16,Cash_Flow_3[Type],"Out",Cash_Flow_3[Category],"Fix") -> 2440568 | L16: =SUMIFS(Cash_Flow_3[Amount],Cash_Flow_3[Bulan],H16,Cash_Flow_3[Type],"Out",Cash_Flow_3[Category],"Bathroom") -> 34500 | M16: =SUMIFS(Cash_Flow_3[Amount],Cash_Flow_3[Bulan],H16,Cash_Flow_3[Type],"Out",Cash_Flow_3[Category],"Alfa") -> 293800 | N16: =SUMIFS(Cash_Flow_3[Amount],Cash_Flow_3[Bulan],H16,Cash_Flow_3[Type],"Out",Cash_Flow_3[Category],"Jajan") -> 364000 | O16: =SUMIFS(Cash_Flow_3[Amount],Cash_Flow_3[Bulan],H16,Cash_Flow_3[Type],"Out",Cash_Flow_3[Category],"Kitchen") -> 992724 | P16: =SUMIFS(Cash_Flow_3[Amount],Cash_Flow_3[Bulan],H16,Cash_Flow_3[Type],"Out",Cash_Flow_3[Category],"Loandry") -> 41600 | Q16: =SUMIFS(Cash_Flow_3[Amount],Cash_Flow_3[Bulan],H16,Cash_Flow_3[Type],"Out",Cash_Flow_3[Category],"Mio") -> 249000 | R16: =SUMIFS(Cash_Flow_3[Amount],Cash_Flow_3[Bulan],H16,Cash_Flow_3[Type],"Out",Cash_Flow_3[Category],"Sedekah") -> 129000 | S16: =SUMIFS(Cash_Flow_3[Amount],Cash_Flow_3[Bulan],H16,Cash_Flow_3[Type],"Out",Cash_Flow_3[Category],"Zela") -> 24100 | T16: =SUMIFS(Cash_Flow_3[Amount],Cash_Flow_3[Bulan],H16,Cash_Flow_3[Type],"Out",Cash_Flow_3[Category],"Iqbal") -> 121000
... A363: 46106 | B363: Pempes Alf a | C363: Cash | D363: Out | E363: Alfa | F363: 42500 | H363: =IF(A363="","", DATE(YEAR(A363),MONTH(A363),1) ) -> 46082 | I363: =SUMIFS(Cash_Flow_3[Amount],Cash_Flow_3[Bulan],H363,Cash_Flow_3[Type],"In") -> 13015393 | J363: =SUMIFS(Cash_Flow_3[Amount],Cash_Flow_3[Bulan],H363,Cash_Flow_3[Type],"Out") -> 10475288 | K363: =SUMIFS(Cash_Flow_3[Amount],Cash_Flow_3[Bulan],H363,Cash_Flow_3[Type],"Out",Cash_Flow_3[Category],"Fix") -> 2908413 | L363: =SUMIFS(Cash_Flow_3[Amount],Cash_Flow_3[Bulan],H363,Cash_Flow_3[Type],"Out",Cash_Flow_3[Category],"Bathroom") -> 48473 | M363: =SUMIFS(Cash_Flow_3[Amount],Cash_Flow_3[Bulan],H363,Cash_Flow_3[Type],"Out",Cash_Flow_3[Category],"Alfa") -> 775042 | N363: =SUMIFS(Cash_Flow_3[Amount],Cash_Flow_3[Bulan],H363,Cash_Flow_3[Type],"Out",Cash_Flow_3[Category],"Jajan") -> 795099 | O363: =SUMIFS(Cash_Flow_3[Amount],Cash_Flow_3[Bulan],H363,Cash_Flow_3[Type],"Out",Cash_Flow_3[Category],"Kitchen") -> 1003600 | P363: =SUMIFS(Cash_Flow_3[Amount],Cash_Flow_3[Bulan],H363,Cash_Flow_3[Type],"Out",Cash_Flow_3[Category],"Loandry") -> 41000 | Q363: =SUMIFS(Cash_Flow_3[Amount],Cash_Flow_3[Bulan],H363,Cash_Flow_3[Type],"Out",Cash_Flow_3[Category],"Mio") -> 364500 | R363: =SUMIFS(Cash_Flow_3[Amount],Cash_Flow_3[Bulan],H363,Cash_Flow_3[Type],"Out",Cash_Flow_3[Category],"Sedekah") -> 130000 | S363: =SUMIFS(Cash_Flow_3[Amount],Cash_Flow_3[Bulan],H363,Cash_Flow_3[Type],"Out",Cash_Flow_3[Category],"Zela") -> 215161 | T363: =SUMIFS(Cash_Flow_3[Amount],Cash_Flow_3[Bulan],H363,Cash_Flow_3[Type],"Out",Cash_Flow_3[Category],"Iqbal") -> 160000
H364: =IF(A364="","", DATE(YEAR(A364),MONTH(A364),1) ) | I364: =SUMIFS(Cash_Flow_3[Amount],Cash_Flow_3[Bulan],H364,Cash_Flow_3[Type],"In") -> 0 | J364: =SUMIFS(Cash_Flow_3[Amount],Cash_Flow_3[Bulan],H364,Cash_Flow_3[Type],"Out") -> 0 | K364: =SUMIFS(Cash_Flow_3[Amount],Cash_Flow_3[Bulan],H364,Cash_Flow_3[Type],"Out",Cash_Flow_3[Category],"Fix") -> 0 | L364: =SUMIFS(Cash_Flow_3[Amount],Cash_Flow_3[Bulan],H364,Cash_Flow_3[Type],"Out",Cash_Flow_3[Category],"Bathroom") -> 0 | M364: =SUMIFS(Cash_Flow_3[Amount],Cash_Flow_3[Bulan],H364,Cash_Flow_3[Type],"Out",Cash_Flow_3[Category],"Alfa") -> 0 | N364: =SUMIFS(Cash_Flow_3[Amount],Cash_Flow_3[Bulan],H364,Cash_Flow_3[Type],"Out",Cash_Flow_3[Category],"Jajan") -> 0 | O364: =SUMIFS(Cash_Flow_3[Amount],Cash_Flow_3[Bulan],H364,Cash_Flow_3[Type],"Out",Cash_Flow_3[Category],"Kitchen") -> 0 | P364: =SUMIFS(Cash_Flow_3[Amount],Cash_Flow_3[Bulan],H364,Cash_Flow_3[Type],"Out",Cash_Flow_3[Category],"Loandry") -> 0 | Q364: =SUMIFS(Cash_Flow_3[Amount],Cash_Flow_3[Bulan],H364,Cash_Flow_3[Type],"Out",Cash_Flow_3[Category],"Mio") -> 0 | R364: =SUMIFS(Cash_Flow_3[Amount],Cash_Flow_3[Bulan],H364,Cash_Flow_3[Type],"Out",Cash_Flow_3[Category],"Sedekah") -> 0 | S364: =SUMIFS(Cash_Flow_3[Amount],Cash_Flow_3[Bulan],H364,Cash_Flow_3[Type],"Out",Cash_Flow_3[Category],"Zela") -> 0 | T364: =SUMIFS(Cash_Flow_3[Amount],Cash_Flow_3[Bulan],H364,Cash_Flow_3[Type],"Out",Cash_Flow_3[Category],"Iqbal") -> 0
H365: =IF(A365="","", DATE(YEAR(A365),MONTH(A365),1) ) | I365: =SUMIFS(Cash_Flow_3[Amount],Cash_Flow_3[Bulan],H365,Cash_Flow_3[Type],"In") -> 0 | J365: =SUMIFS(Cash_Flow_3[Amount],Cash_Flow_3[Bulan],H365,Cash_Flow_3[Type],"Out") -> 0 | K365: =SUMIFS(Cash_Flow_3[Amount],Cash_Flow_3[Bulan],H365,Cash_Flow_3[Type],"Out",Cash_Flow_3[Category],"Fix") -> 0 | L365: =SUMIFS(Cash_Flow_3[Amount],Cash_Flow_3[Bulan],H365,Cash_Flow_3[Type],"Out",Cash_Flow_3[Category],"Bathroom") -> 0 | M365: =SUMIFS(Cash_Flow_3[Amount],Cash_Flow_3[Bulan],H365,Cash_Flow_3[Type],"Out",Cash_Flow_3[Category],"Alfa") -> 0 | N365: =SUMIFS(Cash_Flow_3[Amount],Cash_Flow_3[Bulan],H365,Cash_Flow_3[Type],"Out",Cash_Flow_3[Category],"Jajan") -> 0 | O365: =SUMIFS(Cash_Flow_3[Amount],Cash_Flow_3[Bulan],H365,Cash_Flow_3[Type],"Out",Cash_Flow_3[Category],"Kitchen") -> 0 | P365: =SUMIFS(Cash_Flow_3[Amount],Cash_Flow_3[Bulan],H365,Cash_Flow_3[Type],"Out",Cash_Flow_3[Category],"Loandry") -> 0 | Q365: =SUMIFS(Cash_Flow_3[Amount],Cash_Flow_3[Bulan],H365,Cash_Flow_3[Type],"Out",Cash_Flow_3[Category],"Mio") -> 0 | R365: =SUMIFS(Cash_Flow_3[Amount],Cash_Flow_3[Bulan],H365,Cash_Flow_3[Type],"Out",Cash_Flow_3[Category],"Sedekah") -> 0 | S365: =SUMIFS(Cash_Flow_3[Amount],Cash_Flow_3[Bulan],H365,Cash_Flow_3[Type],"Out",Cash_Flow_3[Category],"Zela") -> 0 | T365: =SUMIFS(Cash_Flow_3[Amount],Cash_Flow_3[Bulan],H365,Cash_Flow_3[Type],"Out",Cash_Flow_3[Category],"Iqbal") -> 0
H366: =IF(A366="","", DATE(YEAR(A366),MONTH(A366),1) ) | I366: =SUMIFS(Cash_Flow_3[Amount],Cash_Flow_3[Bulan],H366,Cash_Flow_3[Type],"In") -> 0 | J366: =SUMIFS(Cash_Flow_3[Amount],Cash_Flow_3[Bulan],H366,Cash_Flow_3[Type],"Out") -> 0 | K366: =SUMIFS(Cash_Flow_3[Amount],Cash_Flow_3[Bulan],H366,Cash_Flow_3[Type],"Out",Cash_Flow_3[Category],"Fix") -> 0 | L366: =SUMIFS(Cash_Flow_3[Amount],Cash_Flow_3[Bulan],H366,Cash_Flow_3[Type],"Out",Cash_Flow_3[Category],"Bathroom") -> 0 | M366: =SUMIFS(Cash_Flow_3[Amount],Cash_Flow_3[Bulan],H366,Cash_Flow_3[Type],"Out",Cash_Flow_3[Category],"Alfa") -> 0 | N366: =SUMIFS(Cash_Flow_3[Amount],Cash_Flow_3[Bulan],H366,Cash_Flow_3[Type],"Out",Cash_Flow_3[Category],"Jajan") -> 0 | O366: =SUMIFS(Cash_Flow_3[Amount],Cash_Flow_3[Bulan],H366,Cash_Flow_3[Type],"Out",Cash_Flow_3[Category],"Kitchen") -> 0 | P366: =SUMIFS(Cash_Flow_3[Amount],Cash_Flow_3[Bulan],H366,Cash_Flow_3[Type],"Out",Cash_Flow_3[Category],"Loandry") -> 0 | Q366: =SUMIFS(Cash_Flow_3[Amount],Cash_Flow_3[Bulan],H366,Cash_Flow_3[Type],"Out",Cash_Flow_3[Category],"Mio") -> 0 | R366: =SUMIFS(Cash_Flow_3[Amount],Cash_Flow_3[Bulan],H366,Cash_Flow_3[Type],"Out",Cash_Flow_3[Category],"Sedekah") -> 0 | S366: =SUMIFS(Cash_Flow_3[Amount],Cash_Flow_3[Bulan],H366,Cash_Flow_3[Type],"Out",Cash_Flow_3[Category],"Zela") -> 0 | T366: =SUMIFS(Cash_Flow_3[Amount],Cash_Flow_3[Bulan],H366,Cash_Flow_3[Type],"Out",Cash_Flow_3[Category],"Iqbal") -> 0
H367: =IF(A367="","", DATE(YEAR(A367),MONTH(A367),1) ) | I367: =SUMIFS(Cash_Flow_3[Amount],Cash_Flow_3[Bulan],H367,Cash_Flow_3[Type],"In") -> 0 | J367: =SUMIFS(Cash_Flow_3[Amount],Cash_Flow_3[Bulan],H367,Cash_Flow_3[Type],"Out") -> 0 | K367: =SUMIFS(Cash_Flow_3[Amount],Cash_Flow_3[Bulan],H367,Cash_Flow_3[Type],"Out",Cash_Flow_3[Category],"Fix") -> 0 | L367: =SUMIFS(Cash_Flow_3[Amount],Cash_Flow_3[Bulan],H367,Cash_Flow_3[Type],"Out",Cash_Flow_3[Category],"Bathroom") -> 0 | M367: =SUMIFS(Cash_Flow_3[Amount],Cash_Flow_3[Bulan],H367,Cash_Flow_3[Type],"Out",Cash_Flow_3[Category],"Alfa") -> 0 | N367: =SUMIFS(Cash_Flow_3[Amount],Cash_Flow_3[Bulan],H367,Cash_Flow_3[Type],"Out",Cash_Flow_3[Category],"Jajan") -> 0 | O367: =SUMIFS(Cash_Flow_3[Amount],Cash_Flow_3[Bulan],H367,Cash_Flow_3[Type],"Out",Cash_Flow_3[Category],"Kitchen") -> 0 | P367: =SUMIFS(Cash_Flow_3[Amount],Cash_Flow_3[Bulan],H367,Cash_Flow_3[Type],"Out",Cash_Flow_3[Category],"Loandry") -> 0 | Q367: =SUMIFS(Cash_Flow_3[Amount],Cash_Flow_3[Bulan],H367,Cash_Flow_3[Type],"Out",Cash_Flow_3[Category],"Mio") -> 0 | R367: =SUMIFS(Cash_Flow_3[Amount],Cash_Flow_3[Bulan],H367,Cash_Flow_3[Type],"Out",Cash_Flow_3[Category],"Sedekah") -> 0 | S367: =SUMIFS(Cash_Flow_3[Amount],Cash_Flow_3[Bulan],H367,Cash_Flow_3[Type],"Out",Cash_Flow_3[Category],"Zela") -> 0 | T367: =SUMIFS(Cash_Flow_3[Amount],Cash_Flow_3[Bulan],H367,Cash_Flow_3[Type],"Out",Cash_Flow_3[Category],"Iqbal") -> 0
H368: =IF(A368="","", DATE(YEAR(A368),MONTH(A368),1) ) | I368: =SUMIFS(Cash_Flow_3[Amount],Cash_Flow_3[Bulan],H368,Cash_Flow_3[Type],"In") -> 0 | J368: =SUMIFS(Cash_Flow_3[Amount],Cash_Flow_3[Bulan],H368,Cash_Flow_3[Type],"Out") -> 0 | K368: =SUMIFS(Cash_Flow_3[Amount],Cash_Flow_3[Bulan],H368,Cash_Flow_3[Type],"Out",Cash_Flow_3[Category],"Fix") -> 0 | L368: =SUMIFS(Cash_Flow_3[Amount],Cash_Flow_3[Bulan],H368,Cash_Flow_3[Type],"Out",Cash_Flow_3[Category],"Bathroom") -> 0 | M368: =SUMIFS(Cash_Flow_3[Amount],Cash_Flow_3[Bulan],H368,Cash_Flow_3[Type],"Out",Cash_Flow_3[Category],"Alfa") -> 0 | N368: =SUMIFS(Cash_Flow_3[Amount],Cash_Flow_3[Bulan],H368,Cash_Flow_3[Type],"Out",Cash_Flow_3[Category],"Jajan") -> 0 | O368: =SUMIFS(Cash_Flow_3[Amount],Cash_Flow_3[Bulan],H368,Cash_Flow_3[Type],"Out",Cash_Flow_3[Category],"Kitchen") -> 0 | P368: =SUMIFS(Cash_Flow_3[Amount],Cash_Flow_3[Bulan],H368,Cash_Flow_3[Type],"Out",Cash_Flow_3[Category],"Loandry") -> 0 | Q368: =SUMIFS(Cash_Flow_3[Amount],Cash_Flow_3[Bulan],H368,Cash_Flow_3[Type],"Out",Cash_Flow_3[Category],"Mio") -> 0 | R368: =SUMIFS(Cash_Flow_3[Amount],Cash_Flow_3[Bulan],H368,Cash_Flow_3[Type],"Out",Cash_Flow_3[Category],"Sedekah") -> 0 | S368: =SUMIFS(Cash_Flow_3[Amount],Cash_Flow_3[Bulan],H368,Cash_Flow_3[Type],"Out",Cash_Flow_3[Category],"Zela") -> 0 | T368: =SUMIFS(Cash_Flow_3[Amount],Cash_Flow_3[Bulan],H368,Cash_Flow_3[Type],"Out",Cash_Flow_3[Category],"Iqbal") -> 0
H369: =IF(A369="","", DATE(YEAR(A369),MONTH(A369),1) ) | I369: =SUMIFS(Cash_Flow_3[Amount],Cash_Flow_3[Bulan],H369,Cash_Flow_3[Type],"In") -> 0 | J369: =SUMIFS(Cash_Flow_3[Amount],Cash_Flow_3[Bulan],H369,Cash_Flow_3[Type],"Out") -> 0 | K369: =SUMIFS(Cash_Flow_3[Amount],Cash_Flow_3[Bulan],H369,Cash_Flow_3[Type],"Out",Cash_Flow_3[Category],"Fix") -> 0 | L369: =SUMIFS(Cash_Flow_3[Amount],Cash_Flow_3[Bulan],H369,Cash_Flow_3[Type],"Out",Cash_Flow_3[Category],"Bathroom") -> 0 | M369: =SUMIFS(Cash_Flow_3[Amount],Cash_Flow_3[Bulan],H369,Cash_Flow_3[Type],"Out",Cash_Flow_3[Category],"Alfa") -> 0 | N369: =SUMIFS(Cash_Flow_3[Amount],Cash_Flow_3[Bulan],H369,Cash_Flow_3[Type],"Out",Cash_Flow_3[Category],"Jajan") -> 0 | O369: =SUMIFS(Cash_Flow_3[Amount],Cash_Flow_3[Bulan],H369,Cash_Flow_3[Type],"Out",Cash_Flow_3[Category],"Kitchen") -> 0 | P369: =SUMIFS(Cash_Flow_3[Amount],Cash_Flow_3[Bulan],H369,Cash_Flow_3[Type],"Out",Cash_Flow_3[Category],"Loandry") -> 0 | Q369: =SUMIFS(Cash_Flow_3[Amount],Cash_Flow_3[Bulan],H369,Cash_Flow_3[Type],"Out",Cash_Flow_3[Category],"Mio") -> 0 | R369: =SUMIFS(Cash_Flow_3[Amount],Cash_Flow_3[Bulan],H369,Cash_Flow_3[Type],"Out",Cash_Flow_3[Category],"Sedekah") -> 0 | S369: =SUMIFS(Cash_Flow_3[Amount],Cash_Flow_3[Bulan],H369,Cash_Flow_3[Type],"Out",Cash_Flow_3[Category],"Zela") -> 0 | T369: =SUMIFS(Cash_Flow_3[Amount],Cash_Flow_3[Bulan],H369,Cash_Flow_3[Type],"Out",Cash_Flow_3[Category],"Iqbal") -> 0
H370: =IF(A370="","", DATE(YEAR(A370),MONTH(A370),1) ) | I370: =SUMIFS(Cash_Flow_3[Amount],Cash_Flow_3[Bulan],H370,Cash_Flow_3[Type],"In") -> 0 | J370: =SUMIFS(Cash_Flow_3[Amount],Cash_Flow_3[Bulan],H370,Cash_Flow_3[Type],"Out") -> 0 | K370: =SUMIFS(Cash_Flow_3[Amount],Cash_Flow_3[Bulan],H370,Cash_Flow_3[Type],"Out",Cash_Flow_3[Category],"Fix") -> 0 | L370: =SUMIFS(Cash_Flow_3[Amount],Cash_Flow_3[Bulan],H370,Cash_Flow_3[Type],"Out",Cash_Flow_3[Category],"Bathroom") -> 0 | M370: =SUMIFS(Cash_Flow_3[Amount],Cash_Flow_3[Bulan],H370,Cash_Flow_3[Type],"Out",Cash_Flow_3[Category],"Alfa") -> 0 | N370: =SUMIFS(Cash_Flow_3[Amount],Cash_Flow_3[Bulan],H370,Cash_Flow_3[Type],"Out",Cash_Flow_3[Category],"Jajan") -> 0 | O370: =SUMIFS(Cash_Flow_3[Amount],Cash_Flow_3[Bulan],H370,Cash_Flow_3[Type],"Out",Cash_Flow_3[Category],"Kitchen") -> 0 | P370: =SUMIFS(Cash_Flow_3[Amount],Cash_Flow_3[Bulan],H370,Cash_Flow_3[Type],"Out",Cash_Flow_3[Category],"Loandry") -> 0 | Q370: =SUMIFS(Cash_Flow_3[Amount],Cash_Flow_3[Bulan],H370,Cash_Flow_3[Type],"Out",Cash_Flow_3[Category],"Mio") -> 0 | R370: =SUMIFS(Cash_Flow_3[Amount],Cash_Flow_3[Bulan],H370,Cash_Flow_3[Type],"Out",Cash_Flow_3[Category],"Sedekah") -> 0 | S370: =SUMIFS(Cash_Flow_3[Amount],Cash_Flow_3[Bulan],H370,Cash_Flow_3[Type],"Out",Cash_Flow_3[Category],"Zela") -> 0 | T370: =SUMIFS(Cash_Flow_3[Amount],Cash_Flow_3[Bulan],H370,Cash_Flow_3[Type],"Out",Cash_Flow_3[Category],"Iqbal") -> 0
H371: =IF(A371="","", DATE(YEAR(A371),MONTH(A371),1) ) | I371: =SUMIFS(Cash_Flow_3[Amount],Cash_Flow_3[Bulan],H371,Cash_Flow_3[Type],"In") -> 0 | J371: =SUMIFS(Cash_Flow_3[Amount],Cash_Flow_3[Bulan],H371,Cash_Flow_3[Type],"Out") -> 0 | K371: =SUMIFS(Cash_Flow_3[Amount],Cash_Flow_3[Bulan],H371,Cash_Flow_3[Type],"Out",Cash_Flow_3[Category],"Fix") -> 0 | L371: =SUMIFS(Cash_Flow_3[Amount],Cash_Flow_3[Bulan],H371,Cash_Flow_3[Type],"Out",Cash_Flow_3[Category],"Bathroom") -> 0 | M371: =SUMIFS(Cash_Flow_3[Amount],Cash_Flow_3[Bulan],H371,Cash_Flow_3[Type],"Out",Cash_Flow_3[Category],"Alfa") -> 0 | N371: =SUMIFS(Cash_Flow_3[Amount],Cash_Flow_3[Bulan],H371,Cash_Flow_3[Type],"Out",Cash_Flow_3[Category],"Jajan") -> 0 | O371: =SUMIFS(Cash_Flow_3[Amount],Cash_Flow_3[Bulan],H371,Cash_Flow_3[Type],"Out",Cash_Flow_3[Category],"Kitchen") -> 0 | P371: =SUMIFS(Cash_Flow_3[Amount],Cash_Flow_3[Bulan],H371,Cash_Flow_3[Type],"Out",Cash_Flow_3[Category],"Loandry") -> 0 | Q371: =SUMIFS(Cash_Flow_3[Amount],Cash_Flow_3[Bulan],H371,Cash_Flow_3[Type],"Out",Cash_Flow_3[Category],"Mio") -> 0 | R371: =SUMIFS(Cash_Flow_3[Amount],Cash_Flow_3[Bulan],H371,Cash_Flow_3[Type],"Out",Cash_Flow_3[Category],"Sedekah") -> 0 | S371: =SUMIFS(Cash_Flow_3[Amount],Cash_Flow_3[Bulan],H371,Cash_Flow_3[Type],"Out",Cash_Flow_3[Category],"Zela") -> 0 | T371: =SUMIFS(Cash_Flow_3[Amount],Cash_Flow_3[Bulan],H371,Cash_Flow_3[Type],"Out",Cash_Flow_3[Category],"Iqbal") -> 0
H372: =IF(A372="","", DATE(YEAR(A372),MONTH(A372),1) ) | I372: =SUMIFS(Cash_Flow_3[Amount],Cash_Flow_3[Bulan],H372,Cash_Flow_3[Type],"In") -> 0 | J372: =SUMIFS(Cash_Flow_3[Amount],Cash_Flow_3[Bulan],H372,Cash_Flow_3[Type],"Out") -> 0 | K372: =SUMIFS(Cash_Flow_3[Amount],Cash_Flow_3[Bulan],H372,Cash_Flow_3[Type],"Out",Cash_Flow_3[Category],"Fix") -> 0 | L372: =SUMIFS(Cash_Flow_3[Amount],Cash_Flow_3[Bulan],H372,Cash_Flow_3[Type],"Out",Cash_Flow_3[Category],"Bathroom") -> 0 | M372: =SUMIFS(Cash_Flow_3[Amount],Cash_Flow_3[Bulan],H372,Cash_Flow_3[Type],"Out",Cash_Flow_3[Category],"Alfa") -> 0 | N372: =SUMIFS(Cash_Flow_3[Amount],Cash_Flow_3[Bulan],H372,Cash_Flow_3[Type],"Out",Cash_Flow_3[Category],"Jajan") -> 0 | O372: =SUMIFS(Cash_Flow_3[Amount],Cash_Flow_3[Bulan],H372,Cash_Flow_3[Type],"Out",Cash_Flow_3[Category],"Kitchen") -> 0 | P372: =SUMIFS(Cash_Flow_3[Amount],Cash_Flow_3[Bulan],H372,Cash_Flow_3[Type],"Out",Cash_Flow_3[Category],"Loandry") -> 0 | Q372: =SUMIFS(Cash_Flow_3[Amount],Cash_Flow_3[Bulan],H372,Cash_Flow_3[Type],"Out",Cash_Flow_3[Category],"Mio") -> 0 | R372: =SUMIFS(Cash_Flow_3[Amount],Cash_Flow_3[Bulan],H372,Cash_Flow_3[Type],"Out",Cash_Flow_3[Category],"Sedekah") -> 0 | S372: =SUMIFS(Cash_Flow_3[Amount],Cash_Flow_3[Bulan],H372,Cash_Flow_3[Type],"Out",Cash_Flow_3[Category],"Zela") -> 0 | T372: =SUMIFS(Cash_Flow_3[Amount],Cash_Flow_3[Bulan],H372,Cash_Flow_3[Type],"Out",Cash_Flow_3[Category],"Iqbal") -> 0
H373: =IF(A373="","", DATE(YEAR(A373),MONTH(A373),1) ) | I373: =SUMIFS(Cash_Flow_3[Amount],Cash_Flow_3[Bulan],H373,Cash_Flow_3[Type],"In") -> 0 | J373: =SUMIFS(Cash_Flow_3[Amount],Cash_Flow_3[Bulan],H373,Cash_Flow_3[Type],"Out") -> 0 | K373: =SUMIFS(Cash_Flow_3[Amount],Cash_Flow_3[Bulan],H373,Cash_Flow_3[Type],"Out",Cash_Flow_3[Category],"Fix") -> 0 | L373: =SUMIFS(Cash_Flow_3[Amount],Cash_Flow_3[Bulan],H373,Cash_Flow_3[Type],"Out",Cash_Flow_3[Category],"Bathroom") -> 0 | M373: =SUMIFS(Cash_Flow_3[Amount],Cash_Flow_3[Bulan],H373,Cash_Flow_3[Type],"Out",Cash_Flow_3[Category],"Alfa") -> 0 | N373: =SUMIFS(Cash_Flow_3[Amount],Cash_Flow_3[Bulan],H373,Cash_Flow_3[Type],"Out",Cash_Flow_3[Category],"Jajan") -> 0 | O373: =SUMIFS(Cash_Flow_3[Amount],Cash_Flow_3[Bulan],H373,Cash_Flow_3[Type],"Out",Cash_Flow_3[Category],"Kitchen") -> 0 | P373: =SUMIFS(Cash_Flow_3[Amount],Cash_Flow_3[Bulan],H373,Cash_Flow_3[Type],"Out",Cash_Flow_3[Category],"Loandry") -> 0 | Q373: =SUMIFS(Cash_Flow_3[Amount],Cash_Flow_3[Bulan],H373,Cash_Flow_3[Type],"Out",Cash_Flow_3[Category],"Mio") -> 0 | R373: =SUMIFS(Cash_Flow_3[Amount],Cash_Flow_3[Bulan],H373,Cash_Flow_3[Type],"Out",Cash_Flow_3[Category],"Sedekah") -> 0 | S373: =SUMIFS(Cash_Flow_3[Amount],Cash_Flow_3[Bulan],H373,Cash_Flow_3[Type],"Out",Cash_Flow_3[Category],"Zela") -> 0 | T373: =SUMIFS(Cash_Flow_3[Amount],Cash_Flow_3[Bulan],H373,Cash_Flow_3[Type],"Out",Cash_Flow_3[Category],"Iqbal") -> 0
H374: =IF(A374="","", DATE(YEAR(A374),MONTH(A374),1) ) | I374: =SUMIFS(Cash_Flow_3[Amount],Cash_Flow_3[Bulan],H374,Cash_Flow_3[Type],"In") -> 0 | J374: =SUMIFS(Cash_Flow_3[Amount],Cash_Flow_3[Bulan],H374,Cash_Flow_3[Type],"Out") -> 0 | K374: =SUMIFS(Cash_Flow_3[Amount],Cash_Flow_3[Bulan],H374,Cash_Flow_3[Type],"Out",Cash_Flow_3[Category],"Fix") -> 0 | L374: =SUMIFS(Cash_Flow_3[Amount],Cash_Flow_3[Bulan],H374,Cash_Flow_3[Type],"Out",Cash_Flow_3[Category],"Bathroom") -> 0 | M374: =SUMIFS(Cash_Flow_3[Amount],Cash_Flow_3[Bulan],H374,Cash_Flow_3[Type],"Out",Cash_Flow_3[Category],"Alfa") -> 0 | N374: =SUMIFS(Cash_Flow_3[Amount],Cash_Flow_3[Bulan],H374,Cash_Flow_3[Type],"Out",Cash_Flow_3[Category],"Jajan") -> 0 | O374: =SUMIFS(Cash_Flow_3[Amount],Cash_Flow_3[Bulan],H374,Cash_Flow_3[Type],"Out",Cash_Flow_3[Category],"Kitchen") -> 0 | P374: =SUMIFS(Cash_Flow_3[Amount],Cash_Flow_3[Bulan],H374,Cash_Flow_3[Type],"Out",Cash_Flow_3[Category],"Loandry") -> 0 | Q374: =SUMIFS(Cash_Flow_3[Amount],Cash_Flow_3[Bulan],H374,Cash_Flow_3[Type],"Out",Cash_Flow_3[Category],"Mio") -> 0 | R374: =SUMIFS(Cash_Flow_3[Amount],Cash_Flow_3[Bulan],H374,Cash_Flow_3[Type],"Out",Cash_Flow_3[Category],"Sedekah") -> 0 | S374: =SUMIFS(Cash_Flow_3[Amount],Cash_Flow_3[Bulan],H374,Cash_Flow_3[Type],"Out",Cash_Flow_3[Category],"Zela") -> 0 | T374: =SUMIFS(Cash_Flow_3[Amount],Cash_Flow_3[Bulan],H374,Cash_Flow_3[Type],"Out",Cash_Flow_3[Category],"Iqbal") -> 0
H375: =IF(A375="","", DATE(YEAR(A375),MONTH(A375),1) ) | I375: =SUMIFS(Cash_Flow_3[Amount],Cash_Flow_3[Bulan],H375,Cash_Flow_3[Type],"In") -> 0 | J375: =SUMIFS(Cash_Flow_3[Amount],Cash_Flow_3[Bulan],H375,Cash_Flow_3[Type],"Out") -> 0 | K375: =SUMIFS(Cash_Flow_3[Amount],Cash_Flow_3[Bulan],H375,Cash_Flow_3[Type],"Out",Cash_Flow_3[Category],"Fix") -> 0 | L375: =SUMIFS(Cash_Flow_3[Amount],Cash_Flow_3[Bulan],H375,Cash_Flow_3[Type],"Out",Cash_Flow_3[Category],"Bathroom") -> 0 | M375: =SUMIFS(Cash_Flow_3[Amount],Cash_Flow_3[Bulan],H375,Cash_Flow_3[Type],"Out",Cash_Flow_3[Category],"Alfa") -> 0 | N375: =SUMIFS(Cash_Flow_3[Amount],Cash_Flow_3[Bulan],H375,Cash_Flow_3[Type],"Out",Cash_Flow_3[Category],"Jajan") -> 0 | O375: =SUMIFS(Cash_Flow_3[Amount],Cash_Flow_3[Bulan],H375,Cash_Flow_3[Type],"Out",Cash_Flow_3[Category],"Kitchen") -> 0 | P375: =SUMIFS(Cash_Flow_3[Amount],Cash_Flow_3[Bulan],H375,Cash_Flow_3[Type],"Out",Cash_Flow_3[Category],"Loandry") -> 0 | Q375: =SUMIFS(Cash_Flow_3[Amount],Cash_Flow_3[Bulan],H375,Cash_Flow_3[Type],"Out",Cash_Flow_3[Category],"Mio") -> 0 | R375: =SUMIFS(Cash_Flow_3[Amount],Cash_Flow_3[Bulan],H375,Cash_Flow_3[Type],"Out",Cash_Flow_3[Category],"Sedekah") -> 0 | S375: =SUMIFS(Cash_Flow_3[Amount],Cash_Flow_3[Bulan],H375,Cash_Flow_3[Type],"Out",Cash_Flow_3[Category],"Zela") -> 0 | T375: =SUMIFS(Cash_Flow_3[Amount],Cash_Flow_3[Bulan],H375,Cash_Flow_3[Type],"Out",Cash_Flow_3[Category],"Iqbal") -> 0
... H1357: =IF(A1357="","", DATE(YEAR(A1357),MONTH(A1357),1) ) | I1357: =SUMIFS(Cash_Flow_3[Amount],Cash_Flow_3[Bulan],H1357,Cash_Flow_3[Type],"In") -> 0 | J1357: =SUMIFS(Cash_Flow_3[Amount],Cash_Flow_3[Bulan],H1357,Cash_Flow_3[Type],"Out") -> 0 | K1357: =SUMIFS(Cash_Flow_3[Amount],Cash_Flow_3[Bulan],H1357,Cash_Flow_3[Type],"Out",Cash_Flow_3[Category],"Fix") -> 0 | L1357: =SUMIFS(Cash_Flow_3[Amount],Cash_Flow_3[Bulan],H1357,Cash_Flow_3[Type],"Out",Cash_Flow_3[Category],"Bathroom") -> 0 | M1357: =SUMIFS(Cash_Flow_3[Amount],Cash_Flow_3[Bulan],H1357,Cash_Flow_3[Type],"Out",Cash_Flow_3[Category],"Alfa") -> 0 | N1357: =SUMIFS(Cash_Flow_3[Amount],Cash_Flow_3[Bulan],H1357,Cash_Flow_3[Type],"Out",Cash_Flow_3[Category],"Jajan") -> 0 | O1357: =SUMIFS(Cash_Flow_3[Amount],Cash_Flow_3[Bulan],H1357,Cash_Flow_3[Type],"Out",Cash_Flow_3[Category],"Kitchen") -> 0 | P1357: =SUMIFS(Cash_Flow_3[Amount],Cash_Flow_3[Bulan],H1357,Cash_Flow_3[Type],"Out",Cash_Flow_3[Category],"Loandry") -> 0 | Q1357: =SUMIFS(Cash_Flow_3[Amount],Cash_Flow_3[Bulan],H1357,Cash_Flow_3[Type],"Out",Cash_Flow_3[Category],"Mio") -> 0 | R1357: =SUMIFS(Cash_Flow_3[Amount],Cash_Flow_3[Bulan],H1357,Cash_Flow_3[Type],"Out",Cash_Flow_3[Category],"Sedekah") -> 0 | S1357: =SUMIFS(Cash_Flow_3[Amount],Cash_Flow_3[Bulan],H1357,Cash_Flow_3[Type],"Out",Cash_Flow_3[Category],"Zela") -> 0 | T1357: =SUMIFS(Cash_Flow_3[Amount],Cash_Flow_3[Bulan],H1357,Cash_Flow_3[Type],"Out",Cash_Flow_3[Category],"Iqbal") -> 0

Sheet CHART_1

Sheet Detail
F1: Fix | G1: Alfa | H1: Jajan | I1: Kitchen | J1: Bathroom | K1: Loandry | L1: Mio | M1: Zela | N1: Iqbal | O1: Move | P1: Sedekah
F2: Iqbal (Shopee) | G2: Popok | I2: Pasar | J2: Pepsodent | K2: Rinso | L2: Bensin | M2: Pembalut | N2: Rokok
F3: Kulkas (Shopee) | G3: Lainnya | I3: Sendok | J3: Lainnya | K3: Lainnya | L3: Lainnya | M3: Bedak | N3: Potong Rambut
F4: Bracket TV (Shopee) | I4: Sunlight | M4: Lainnya
F5: Antena TV (Shopee) | I5: Lainnya
F6: Sewa Rumah
F7: Iuran Komplek
B8: Saldo Awal Iqbal | C8: 15590 | F8: Listrik
B9: Pinjam uang Adi | C9: 300000 | F9: Paket Internet
B10: Gaji Januari 2026 | C10: 4353235
B11: Aulia | C11: 300000
B12: Saldo Awal Zela | C12: 27737
B13: Tiktok | C13: 11566
B14: Dikssi Nenek Prawang (Alfa) | C14: 15000
B15: Total IN | C15: =SUM(C8:C14) -> 5023128 | D15: Total IN | E15: =C15 -> 5023128
B16: IN (Iqbal) + IN (Zela) | C16: =Ibal!B1+Zela!B1 -> -16487496 | D16: TEST | E16: =OUT_1!B1 -> 11528011
B17: Selisih | C17: =C16-C15 -> -21510624 | D17: Selisih | E17: =E16-E15 -> 6504883

Sheet OUT
A1: =IFERROR(__xludf.DUMMYFUNCTION("QUERY(VSTACK(HSTACK(Ibal!A4:F1002, MAP(Ibal!A4:A1002, LAMBDA(x, IF(x=""Date"", ""User"", ""Ibal"")))), HSTACK(Zela!A5:F979, MAP(Zela!A5:A979, LAMBDA(x, ""Zela"")))), ""SELECT * WHERE Col1 IS NOT NULL"")"),"Date") -> Date | B1: =IFERROR(__xludf.DUMMYFUNCTION("""COMPUTED_VALUE"""),"Description") -> Description | C1: =IFERROR(__xludf.DUMMYFUNCTION("""COMPUTED_VALUE"""),"ATM/Cash") -> ATM/Cash | D1: =IFERROR(__xludf.DUMMYFUNCTION("""COMPUTED_VALUE"""),"Type") -> Type | E1: =IFERROR(__xludf.DUMMYFUNCTION("""COMPUTED_VALUE"""),"Category") -> Category | F1: =IFERROR(__xludf.DUMMYFUNCTION("""COMPUTED_VALUE"""),"Amount") -> Amount | G1: =IFERROR(__xludf.DUMMYFUNCTION("""COMPUTED_VALUE"""),"User") -> User | H1: Bulan | I1: In | J1: Out | K1: Fix | L1: Bathroom | M1: Alfa | N1: Jajan | O1: Kitchen | P1: Loandry | Q1: Mio | R1: Sedekah | S1: Zela | T1: Iqbal
A2: =IFERROR(__xludf.DUMMYFUNCTION("""COMPUTED_VALUE"""),46050) -> 46050 | B2: =IFERROR(__xludf.DUMMYFUNCTION("""COMPUTED_VALUE"""),"Saldo Awal") -> Saldo Awal | C2: =IFERROR(__xludf.DUMMYFUNCTION("""COMPUTED_VALUE"""),"ATM") -> ATM | D2: =IFERROR(__xludf.DUMMYFUNCTION("""COMPUTED_VALUE"""),"In") -> In | E2: =IFERROR(__xludf.DUMMYFUNCTION("""COMPUTED_VALUE"""),"Fix") -> Fix | F2: =IFERROR(__xludf.DUMMYFUNCTION("""COMPUTED_VALUE"""),15590) -> 15590 | G2: =IFERROR(__xludf.DUMMYFUNCTION("""COMPUTED_VALUE"""),"Ibal") -> Ibal | H2: =IF(A2="","", DATE(YEAR(A2),MONTH(A2),1) ) -> 46023 | I2: =SUMIFS(OUT!$F$2:$F$11000,OUT!$H$2:$H$11000,H2,OUT!$D$2:$D$101007,"In") -> #VALUE! | J2: =SUMIFS(OUT!$F$2:$F$11000,OUT!$H$2:$H$11000,H2,OUT!$D$2:$D$11000,"Out") -> 475850 | K2: =SUMIFS(OUT!$F$2:$F$11000,OUT!$H$2:$H$11000,H2,OUT!$D$2:$D$11000,"Out",OUT!$E$2:$E$11000,"Fix") -> 114450 | L2: =SUMIFS(OUT!$F$2:$F$11000,OUT!$H$2:$H$11000,H2,OUT!$D$2:$D$11000,"Out",OUT!$E$2:$E$11000,"Bathroom") -> 0 | M2: =SUMIFS(OUT!$F$2:$F$11000,OUT!$H$2:$H$11000,H2,OUT!$D$2:$D$11000,"Out",OUT!$E$2:$E$11000,"Alfa") -> 36400 | N2: =SUMIFS(OUT!$F$2:$F$11000,OUT!$H$2:$H$101007,H2,OUT!$D$2:$D$11000,"Out",OUT!$E$2:$E$11000,"Jajan") -> #VALUE! | O2: =SUMIFS(OUT!$F$2:$F$11000,OUT!$H$2:$H$11000,H2,OUT!$D$2:$D$11000,"Out",OUT!$E$2:$E$11000,"Kitchen") -> 87000 | P2: =SUMIFS(OUT!$F$2:$F$11000,OUT!$H$2:$H$11000,H2,OUT!$D$2:$D$11000,"Out",OUT!$E$2:$E$11000,"Loandry") -> 0 | Q2: =SUMIFS(OUT!$F$2:$F$11000,OUT!$H$2:$H$11000,H2,OUT!$D$2:$D$11000,"Out",OUT!$E$2:$E$11000,"Mio") -> 0 | R2: =SUMIFS(OUT!$F$2:$F$11000,OUT!$H$2:$H$11000,H2,OUT!$D$2:$D$11000,"Out",OUT!$E$2:$E$11000,"Sedekah") -> 0 | S2: =SUMIFS(OUT!$F$2:$F$11000,OUT!$H$2:$H$11000,H2,OUT!$D$2:$D$11000,"Out",OUT!$E$2:$E$11000,"Zela") -> 0 | T2: =SUMIFS(OUT!$F$2:$F$11000,OUT!$H$2:$H$11000,H2,OUT!$D$2:$D$11000,"Out",OUT!$E$2:$E$11000,"Iqbal") -> 0
A3: =IFERROR(__xludf.DUMMYFUNCTION("""COMPUTED_VALUE"""),46051) -> 46051 | B3: =IFERROR(__xludf.DUMMYFUNCTION("""COMPUTED_VALUE"""),"Pinjam uang Adi") -> Pinjam uang Adi | C3: =IFERROR(__xludf.DUMMYFUNCTION("""COMPUTED_VALUE"""),"ATM") -> ATM | D3: =IFERROR(__xludf.DUMMYFUNCTION("""COMPUTED_VALUE"""),"In") -> In | E3: =IFERROR(__xludf.DUMMYFUNCTION("""COMPUTED_VALUE"""),"Fix") -> Fix | F3: =IFERROR(__xludf.DUMMYFUNCTION("""COMPUTED_VALUE"""),300000) -> 300000 | G3: =IFERROR(__xludf.DUMMYFUNCTION("""COMPUTED_VALUE"""),"Ibal") -> Ibal | H3: =IF(A3="","", DATE(YEAR(A3),MONTH(A3),1) ) -> 46023 | I3: =SUMIFS(OUT!$F$2:$F$11000,OUT!$H$2:$H$11000,H3,OUT!$D$2:$D$101007,"In") -> #VALUE! | J3: =SUMIFS(OUT!$F$2:$F$11000,OUT!$H$2:$H$11000,H3,OUT!$D$2:$D$11000,"Out") -> 475850 | K3: =SUMIFS(OUT!$F$2:$F$11000,OUT!$H$2:$H$11000,H3,OUT!$D$2:$D$11000,"Out",OUT!$E$2:$E$11000,"Fix") -> 114450 | L3: =SUMIFS(OUT!$F$2:$F$11000,OUT!$H$2:$H$11000,H3,OUT!$D$2:$D$11000,"Out",OUT!$E$2:$E$11000,"Bathroom") -> 0 | M3: =SUMIFS(OUT!$F$2:$F$11000,OUT!$H$2:$H$11000,H3,OUT!$D$2:$D$11000,"Out",OUT!$E$2:$E$11000,"Alfa") -> 36400 | N3: =SUMIFS(OUT!$F$2:$F$11000,OUT!$H$2:$H$101007,H3,OUT!$D$2:$D$11000,"Out",OUT!$E$2:$E$11000,"Jajan") -> #VALUE! | O3: =SUMIFS(OUT!$F$2:$F$11000,OUT!$H$2:$H$11000,H3,OUT!$D$2:$D$11000,"Out",OUT!$E$2:$E$11000,"Kitchen") -> 87000 | P3: =SUMIFS(OUT!$F$2:$F$11000,OUT!$H$2:$H$11000,H3,OUT!$D$2:$D$11000,"Out",OUT!$E$2:$E$11000,"Loandry") -> 0 | Q3: =SUMIFS(OUT!$F$2:$F$11000,OUT!$H$2:$H$11000,H3,OUT!$D$2:$D$11000,"Out",OUT!$E$2:$E$11000,"Mio") -> 0 | R3: =SUMIFS(OUT!$F$2:$F$11000,OUT!$H$2:$H$11000,H3,OUT!$D$2:$D$11000,"Out",OUT!$E$2:$E$11000,"Sedekah") -> 0 | S3: =SUMIFS(OUT!$F$2:$F$11000,OUT!$H$2:$H$11000,H3,OUT!$D$2:$D$11000,"Out",OUT!$E$2:$E$11000,"Zela") -> 0 | T3: =SUMIFS(OUT!$F$2:$F$11000,OUT!$H$2:$H$11000,H3,OUT!$D$2:$D$11000,"Out",OUT!$E$2:$E$11000,"Iqbal") -> 0
A4: =IFERROR(__xludf.DUMMYFUNCTION("""COMPUTED_VALUE"""),46051) -> 46051 | B4: =IFERROR(__xludf.DUMMYFUNCTION("""COMPUTED_VALUE"""),"Istriku") -> Istriku | C4: =IFERROR(__xludf.DUMMYFUNCTION("""COMPUTED_VALUE"""),"ATM") -> ATM | D4: =IFERROR(__xludf.DUMMYFUNCTION("""COMPUTED_VALUE"""),"Out") -> Out | E4: =IFERROR(__xludf.DUMMYFUNCTION("""COMPUTED_VALUE"""),"Move") -> Move | F4: =IFERROR(__xludf.DUMMYFUNCTION("""COMPUTED_VALUE"""),150000) -> 150000 | G4: =IFERROR(__xludf.DUMMYFUNCTION("""COMPUTED_VALUE"""),"Ibal") -> Ibal | H4: =IF(A4="","", DATE(YEAR(A4),MONTH(A4),1) ) -> 46023 | I4: =SUMIFS(OUT!$F$2:$F$11000,OUT!$H$2:$H$11000,H4,OUT!$D$2:$D$101007,"In") -> #VALUE! | J4: =SUMIFS(OUT!$F$2:$F$11000,OUT!$H$2:$H$11000,H4,OUT!$D$2:$D$11000,"Out") -> 475850 | K4: =SUMIFS(OUT!$F$2:$F$11000,OUT!$H$2:$H$11000,H4,OUT!$D$2:$D$11000,"Out",OUT!$E$2:$E$11000,"Fix") -> 114450 | L4: =SUMIFS(OUT!$F$2:$F$11000,OUT!$H$2:$H$11000,H4,OUT!$D$2:$D$11000,"Out",OUT!$E$2:$E$11000,"Bathroom") -> 0 | M4: =SUMIFS(OUT!$F$2:$F$11000,OUT!$H$2:$H$11000,H4,OUT!$D$2:$D$11000,"Out",OUT!$E$2:$E$11000,"Alfa") -> 36400 | N4: =SUMIFS(OUT!$F$2:$F$11000,OUT!$H$2:$H$101007,H4,OUT!$D$2:$D$11000,"Out",OUT!$E$2:$E$11000,"Jajan") -> #VALUE! | O4: =SUMIFS(OUT!$F$2:$F$11000,OUT!$H$2:$H$11000,H4,OUT!$D$2:$D$11000,"Out",OUT!$E$2:$E$11000,"Kitchen") -> 87000 | P4: =SUMIFS(OUT!$F$2:$F$11000,OUT!$H$2:$H$11000,H4,OUT!$D$2:$D$11000,"Out",OUT!$E$2:$E$11000,"Loandry") -> 0 | Q4: =SUMIFS(OUT!$F$2:$F$11000,OUT!$H$2:$H$11000,H4,OUT!$D$2:$D$11000,"Out",OUT!$E$2:$E$11000,"Mio") -> 0 | R4: =SUMIFS(OUT!$F$2:$F$11000,OUT!$H$2:$H$11000,H4,OUT!$D$2:$D$11000,"Out",OUT!$E$2:$E$11000,"Sedekah") -> 0 | S4: =SUMIFS(OUT!$F$2:$F$11000,OUT!$H$2:$H$11000,H4,OUT!$D$2:$D$11000,"Out",OUT!$E$2:$E$11000,"Zela") -> 0 | T4: =SUMIFS(OUT!$F$2:$F$11000,OUT!$H$2:$H$11000,H4,OUT!$D$2:$D$11000,"Out",OUT!$E$2:$E$11000,"Iqbal") -> 0
A5: =IFERROR(__xludf.DUMMYFUNCTION("""COMPUTED_VALUE"""),46051) -> 46051 | B5: =IFERROR(__xludf.DUMMYFUNCTION("""COMPUTED_VALUE"""),"Token listrik 100k (65,30 kwh)") -> Token listrik 100k (65,30 kwh) | C5: =IFERROR(__xludf.DUMMYFUNCTION("""COMPUTED_VALUE"""),"ATM") -> ATM | D5: =IFERROR(__xludf.DUMMYFUNCTION("""COMPUTED_VALUE"""),"Out") -> Out | E5: =IFERROR(__xludf.DUMMYFUNCTION("""COMPUTED_VALUE"""),"Fix") -> Fix | F5: =IFERROR(__xludf.DUMMYFUNCTION("""COMPUTED_VALUE"""),99450) -> 99450 | G5: =IFERROR(__xludf.DUMMYFUNCTION("""COMPUTED_VALUE"""),"Ibal") -> Ibal | H5: =IF(A5="","", DATE(YEAR(A5),MONTH(A5),1) ) -> 46023 | I5: =SUMIFS(OUT!$F$2:$F$11000,OUT!$H$2:$H$11000,H5,OUT!$D$2:$D$101007,"In") -> #VALUE! | J5: =SUMIFS(OUT!$F$2:$F$11000,OUT!$H$2:$H$11000,H5,OUT!$D$2:$D$11000,"Out") -> 475850 | K5: =SUMIFS(OUT!$F$2:$F$11000,OUT!$H$2:$H$11000,H5,OUT!$D$2:$D$11000,"Out",OUT!$E$2:$E$11000,"Fix") -> 114450 | L5: =SUMIFS(OUT!$F$2:$F$11000,OUT!$H$2:$H$11000,H5,OUT!$D$2:$D$11000,"Out",OUT!$E$2:$E$11000,"Bathroom") -> 0 | M5: =SUMIFS(OUT!$F$2:$F$11000,OUT!$H$2:$H$11000,H5,OUT!$D$2:$D$11000,"Out",OUT!$E$2:$E$11000,"Alfa") -> 36400 | N5: =SUMIFS(OUT!$F$2:$F$11000,OUT!$H$2:$H$101007,H5,OUT!$D$2:$D$11000,"Out",OUT!$E$2:$E$11000,"Jajan") -> #VALUE! | O5: =SUMIFS(OUT!$F$2:$F$11000,OUT!$H$2:$H$11000,H5,OUT!$D$2:$D$11000,"Out",OUT!$E$2:$E$11000,"Kitchen") -> 87000 | P5: =SUMIFS(OUT!$F$2:$F$11000,OUT!$H$2:$H$11000,H5,OUT!$D$2:$D$11000,"Out",OUT!$E$2:$E$11000,"Loandry") -> 0 | Q5: =SUMIFS(OUT!$F$2:$F$11000,OUT!$H$2:$H$11000,H5,OUT!$D$2:$D$11000,"Out",OUT!$E$2:$E$11000,"Mio") -> 0 | R5: =SUMIFS(OUT!$F$2:$F$11000,OUT!$H$2:$H$11000,H5,OUT!$D$2:$D$11000,"Out",OUT!$E$2:$E$11000,"Sedekah") -> 0 | S5: =SUMIFS(OUT!$F$2:$F$11000,OUT!$H$2:$H$11000,H5,OUT!$D$2:$D$11000,"Out",OUT!$E$2:$E$11000,"Zela") -> 0 | T5: =SUMIFS(OUT!$F$2:$F$11000,OUT!$H$2:$H$11000,H5,OUT!$D$2:$D$11000,"Out",OUT!$E$2:$E$11000,"Iqbal") -> 0
A6: =IFERROR(__xludf.DUMMYFUNCTION("""COMPUTED_VALUE"""),46052) -> 46052 | B6: =IFERROR(__xludf.DUMMYFUNCTION("""COMPUTED_VALUE"""),"Istriku") -> Istriku | C6: =IFERROR(__xludf.DUMMYFUNCTION("""COMPUTED_VALUE"""),"ATM") -> ATM | D6: =IFERROR(__xludf.DUMMYFUNCTION("""COMPUTED_VALUE"""),"Out") -> Out | E6: =IFERROR(__xludf.DUMMYFUNCTION("""COMPUTED_VALUE"""),"Move") -> Move | F6: =IFERROR(__xludf.DUMMYFUNCTION("""COMPUTED_VALUE"""),50000) -> 50000 | G6: =IFERROR(__xludf.DUMMYFUNCTION("""COMPUTED_VALUE"""),"Ibal") -> Ibal | H6: =IF(A6="","", DATE(YEAR(A6),MONTH(A6),1) ) -> 46023 | I6: =SUMIFS(OUT!$F$2:$F$11000,OUT!$H$2:$H$11000,H6,OUT!$D$2:$D$101007,"In") -> #VALUE! | J6: =SUMIFS(OUT!$F$2:$F$11000,OUT!$H$2:$H$11000,H6,OUT!$D$2:$D$11000,"Out") -> 475850 | K6: =SUMIFS(OUT!$F$2:$F$11000,OUT!$H$2:$H$11000,H6,OUT!$D$2:$D$11000,"Out",OUT!$E$2:$E$11000,"Fix") -> 114450 | L6: =SUMIFS(OUT!$F$2:$F$11000,OUT!$H$2:$H$11000,H6,OUT!$D$2:$D$11000,"Out",OUT!$E$2:$E$11000,"Bathroom") -> 0 | M6: =SUMIFS(OUT!$F$2:$F$11000,OUT!$H$2:$H$11000,H6,OUT!$D$2:$D$11000,"Out",OUT!$E$2:$E$11000,"Alfa") -> 36400 | N6: =SUMIFS(OUT!$F$2:$F$11000,OUT!$H$2:$H$101007,H6,OUT!$D$2:$D$11000,"Out",OUT!$E$2:$E$11000,"Jajan") -> #VALUE! | O6: =SUMIFS(OUT!$F$2:$F$11000,OUT!$H$2:$H$11000,H6,OUT!$D$2:$D$11000,"Out",OUT!$E$2:$E$11000,"Kitchen") -> 87000 | P6: =SUMIFS(OUT!$F$2:$F$11000,OUT!$H$2:$H$11000,H6,OUT!$D$2:$D$11000,"Out",OUT!$E$2:$E$11000,"Loandry") -> 0 | Q6: =SUMIFS(OUT!$F$2:$F$11000,OUT!$H$2:$H$11000,H6,OUT!$D$2:$D$11000,"Out",OUT!$E$2:$E$11000,"Mio") -> 0 | R6: =SUMIFS(OUT!$F$2:$F$11000,OUT!$H$2:$H$11000,H6,OUT!$D$2:$D$11000,"Out",OUT!$E$2:$E$11000,"Sedekah") -> 0 | S6: =SUMIFS(OUT!$F$2:$F$11000,OUT!$H$2:$H$11000,H6,OUT!$D$2:$D$11000,"Out",OUT!$E$2:$E$11000,"Zela") -> 0 | T6: =SUMIFS(OUT!$F$2:$F$11000,OUT!$H$2:$H$11000,H6,OUT!$D$2:$D$11000,"Out",OUT!$E$2:$E$11000,"Iqbal") -> 0
A7: =IFERROR(__xludf.DUMMYFUNCTION("""COMPUTED_VALUE"""),46055) -> 46055 | B7: =IFERROR(__xludf.DUMMYFUNCTION("""COMPUTED_VALUE"""),"Gaji Januari 2026") -> Gaji Januari 2026 | C7: =IFERROR(__xludf.DUMMYFUNCTION("""COMPUTED_VALUE"""),"ATM") -> ATM | D7: =IFERROR(__xludf.DUMMYFUNCTION("""COMPUTED_VALUE"""),"In") -> In | E7: =IFERROR(__xludf.DUMMYFUNCTION("""COMPUTED_VALUE"""),"Fix") -> Fix | F7: =IFERROR(__xludf.DUMMYFUNCTION("""COMPUTED_VALUE"""),4353235) -> 4353235 | G7: =IFERROR(__xludf.DUMMYFUNCTION("""COMPUTED_VALUE"""),"Ibal") -> Ibal | H7: =IF(A7="","", DATE(YEAR(A7),MONTH(A7),1) ) -> 46054 | I7: =SUMIFS(OUT!$F$2:$F$11000,OUT!$H$2:$H$11000,H7,OUT!$D$2:$D$101007,"In") -> #VALUE! | J7: =SUMIFS(OUT!$F$2:$F$11000,OUT!$H$2:$H$11000,H7,OUT!$D$2:$D$11000,"Out") -> 6908733 | K7: =SUMIFS(OUT!$F$2:$F$11000,OUT!$H$2:$H$11000,H7,OUT!$D$2:$D$11000,"Out",OUT!$E$2:$E$11000,"Fix") -> 2440568 | L7: =SUMIFS(OUT!$F$2:$F$11000,OUT!$H$2:$H$11000,H7,OUT!$D$2:$D$11000,"Out",OUT!$E$2:$E$11000,"Bathroom") -> 34500 | M7: =SUMIFS(OUT!$F$2:$F$11000,OUT!$H$2:$H$11000,H7,OUT!$D$2:$D$11000,"Out",OUT!$E$2:$E$11000,"Alfa") -> 293800 | N7: =SUMIFS(OUT!$F$2:$F$11000,OUT!$H$2:$H$101007,H7,OUT!$D$2:$D$11000,"Out",OUT!$E$2:$E$11000,"Jajan") -> #VALUE! | O7: =SUMIFS(OUT!$F$2:$F$11000,OUT!$H$2:$H$11000,H7,OUT!$D$2:$D$11000,"Out",OUT!$E$2:$E$11000,"Kitchen") -> 992724 | P7: =SUMIFS(OUT!$F$2:$F$11000,OUT!$H$2:$H$11000,H7,OUT!$D$2:$D$11000,"Out",OUT!$E$2:$E$11000,"Loandry") -> 41600 | Q7: =SUMIFS(OUT!$F$2:$F$11000,OUT!$H$2:$H$11000,H7,OUT!$D$2:$D$11000,"Out",OUT!$E$2:$E$11000,"Mio") -> 249000 | R7: =SUMIFS(OUT!$F$2:$F$11000,OUT!$H$2:$H$11000,H7,OUT!$D$2:$D$11000,"Out",OUT!$E$2:$E$11000,"Sedekah") -> 129000 | S7: =SUMIFS(OUT!$F$2:$F$11000,OUT!$H$2:$H$11000,H7,OUT!$D$2:$D$11000,"Out",OUT!$E$2:$E$11000,"Zela") -> 24100 | T7: =SUMIFS(OUT!$F$2:$F$11000,OUT!$H$2:$H$11000,H7,OUT!$D$2:$D$11000,"Out",OUT!$E$2:$E$11000,"Iqbal") -> 121000
A8: =IFERROR(__xludf.DUMMYFUNCTION("""COMPUTED_VALUE"""),46055) -> 46055 | B8: =IFERROR(__xludf.DUMMYFUNCTION("""COMPUTED_VALUE"""),"Byu 10GB") -> Byu 10GB | C8: =IFERROR(__xludf.DUMMYFUNCTION("""COMPUTED_VALUE"""),"ATM") -> ATM | D8: =IFERROR(__xludf.DUMMYFUNCTION("""COMPUTED_VALUE"""),"Out") -> Out | E8: =IFERROR(__xludf.DUMMYFUNCTION("""COMPUTED_VALUE"""),"Fix") -> Fix | F8: =IFERROR(__xludf.DUMMYFUNCTION("""COMPUTED_VALUE"""),25000) -> 25000 | G8: =IFERROR(__xludf.DUMMYFUNCTION("""COMPUTED_VALUE"""),"Ibal") -> Ibal | H8: =IF(A8="","", DATE(YEAR(A8),MONTH(A8),1) ) -> 46054 | I8: =SUMIFS(OUT!$F$2:$F$11000,OUT!$H$2:$H$11000,H8,OUT!$D$2:$D$101007,"In") -> #VALUE! | J8: =SUMIFS(OUT!$F$2:$F$11000,OUT!$H$2:$H$11000,H8,OUT!$D$2:$D$11000,"Out") -> 6908733 | K8: =SUMIFS(OUT!$F$2:$F$11000,OUT!$H$2:$H$11000,H8,OUT!$D$2:$D$11000,"Out",OUT!$E$2:$E$11000,"Fix") -> 2440568 | L8: =SUMIFS(OUT!$F$2:$F$11000,OUT!$H$2:$H$11000,H8,OUT!$D$2:$D$11000,"Out",OUT!$E$2:$E$11000,"Bathroom") -> 34500 | M8: =SUMIFS(OUT!$F$2:$F$11000,OUT!$H$2:$H$11000,H8,OUT!$D$2:$D$11000,"Out",OUT!$E$2:$E$11000,"Alfa") -> 293800 | N8: =SUMIFS(OUT!$F$2:$F$11000,OUT!$H$2:$H$101007,H8,OUT!$D$2:$D$11000,"Out",OUT!$E$2:$E$11000,"Jajan") -> #VALUE! | O8: =SUMIFS(OUT!$F$2:$F$11000,OUT!$H$2:$H$11000,H8,OUT!$D$2:$D$11000,"Out",OUT!$E$2:$E$11000,"Kitchen") -> 992724 | P8: =SUMIFS(OUT!$F$2:$F$11000,OUT!$H$2:$H$11000,H8,OUT!$D$2:$D$11000,"Out",OUT!$E$2:$E$11000,"Loandry") -> 41600 | Q8: =SUMIFS(OUT!$F$2:$F$11000,OUT!$H$2:$H$11000,H8,OUT!$D$2:$D$11000,"Out",OUT!$E$2:$E$11000,"Mio") -> 249000 | R8: =SUMIFS(OUT!$F$2:$F$11000,OUT!$H$2:$H$11000,H8,OUT!$D$2:$D$11000,"Out",OUT!$E$2:$E$11000,"Sedekah") -> 129000 | S8: =SUMIFS(OUT!$F$2:$F$11000,OUT!$H$2:$H$11000,H8,OUT!$D$2:$D$11000,"Out",OUT!$E$2:$E$11000,"Zela") -> 24100 | T8: =SUMIFS(OUT!$F$2:$F$11000,OUT!$H$2:$H$11000,H8,OUT!$D$2:$D$11000,"Out",OUT!$E$2:$E$11000,"Iqbal") -> 121000
A9: =IFERROR(__xludf.DUMMYFUNCTION("""COMPUTED_VALUE"""),46055) -> 46055 | B9: =IFERROR(__xludf.DUMMYFUNCTION("""COMPUTED_VALUE"""),"Istriku") -> Istriku | C9: =IFERROR(__xludf.DUMMYFUNCTION("""COMPUTED_VALUE"""),"ATM") -> ATM | D9: =IFERROR(__xludf.DUMMYFUNCTION("""COMPUTED_VALUE"""),"Out") -> Out | E9: =IFERROR(__xludf.DUMMYFUNCTION("""COMPUTED_VALUE"""),"Move") -> Move | F9: =IFERROR(__xludf.DUMMYFUNCTION("""COMPUTED_VALUE"""),1774441) -> 1774441 | G9: =IFERROR(__xludf.DUMMYFUNCTION("""COMPUTED_VALUE"""),"Ibal") -> Ibal | H9: =IF(A9="","", DATE(YEAR(A9),MONTH(A9),1) ) -> 46054 | I9: =SUMIFS(OUT!$F$2:$F$11000,OUT!$H$2:$H$11000,H9,OUT!$D$2:$D$101007,"In") -> #VALUE! | J9: =SUMIFS(OUT!$F$2:$F$11000,OUT!$H$2:$H$11000,H9,OUT!$D$2:$D$11000,"Out") -> 6908733 | K9: =SUMIFS(OUT!$F$2:$F$11000,OUT!$H$2:$H$11000,H9,OUT!$D$2:$D$11000,"Out",OUT!$E$2:$E$11000,"Fix") -> 2440568 | L9: =SUMIFS(OUT!$F$2:$F$11000,OUT!$H$2:$H$11000,H9,OUT!$D$2:$D$11000,"Out",OUT!$E$2:$E$11000,"Bathroom") -> 34500 | M9: =SUMIFS(OUT!$F$2:$F$11000,OUT!$H$2:$H$11000,H9,OUT!$D$2:$D$11000,"Out",OUT!$E$2:$E$11000,"Alfa") -> 293800 | N9: =SUMIFS(OUT!$F$2:$F$11000,OUT!$H$2:$H$101007,H9,OUT!$D$2:$D$11000,"Out",OUT!$E$2:$E$11000,"Jajan") -> #VALUE! | O9: =SUMIFS(OUT!$F$2:$F$11000,OUT!$H$2:$H$11000,H9,OUT!$D$2:$D$11000,"Out",OUT!$E$2:$E$11000,"Kitchen") -> 992724 | P9: =SUMIFS(OUT!$F$2:$F$11000,OUT!$H$2:$H$11000,H9,OUT!$D$2:$D$11000,"Out",OUT!$E$2:$E$11000,"Loandry") -> 41600 | Q9: =SUMIFS(OUT!$F$2:$F$11000,OUT!$H$2:$H$11000,H9,OUT!$D$2:$D$11000,"Out",OUT!$E$2:$E$11000,"Mio") -> 249000 | R9: =SUMIFS(OUT!$F$2:$F$11000,OUT!$H$2:$H$11000,H9,OUT!$D$2:$D$11000,"Out",OUT!$E$2:$E$11000,"Sedekah") -> 129000 | S9: =SUMIFS(OUT!$F$2:$F$11000,OUT!$H$2:$H$11000,H9,OUT!$D$2:$D$11000,"Out",OUT!$E$2:$E$11000,"Zela") -> 24100 | T9: =SUMIFS(OUT!$F$2:$F$11000,OUT!$H$2:$H$11000,H9,OUT!$D$2:$D$11000,"Out",OUT!$E$2:$E$11000,"Iqbal") -> 121000
A10: =IFERROR(__xludf.DUMMYFUNCTION("""COMPUTED_VALUE"""),46055) -> 46055 | B10: =IFERROR(__xludf.DUMMYFUNCTION("""COMPUTED_VALUE"""),"Bayar uang Adi") -> Bayar uang Adi | C10: =IFERROR(__xludf.DUMMYFUNCTION("""COMPUTED_VALUE"""),"ATM") -> ATM | D10: =IFERROR(__xludf.DUMMYFUNCTION("""COMPUTED_VALUE"""),"Out") -> Out | E10: =IFERROR(__xludf.DUMMYFUNCTION("""COMPUTED_VALUE"""),"Fix") -> Fix | F10: =IFERROR(__xludf.DUMMYFUNCTION("""COMPUTED_VALUE"""),300000) -> 300000 | G10: =IFERROR(__xludf.DUMMYFUNCTION("""COMPUTED_VALUE"""),"Ibal") -> Ibal | H10: =IF(A10="","", DATE(YEAR(A10),MONTH(A10),1) ) -> 46054 | I10: =SUMIFS(OUT!$F$2:$F$11000,OUT!$H$2:$H$11000,H10,OUT!$D$2:$D$101007,"In") -> #VALUE! | J10: =SUMIFS(OUT!$F$2:$F$11000,OUT!$H$2:$H$11000,H10,OUT!$D$2:$D$11000,"Out") -> 6908733 | K10: =SUMIFS(OUT!$F$2:$F$11000,OUT!$H$2:$H$11000,H10,OUT!$D$2:$D$11000,"Out",OUT!$E$2:$E$11000,"Fix") -> 2440568 | L10: =SUMIFS(OUT!$F$2:$F$11000,OUT!$H$2:$H$11000,H10,OUT!$D$2:$D$11000,"Out",OUT!$E$2:$E$11000,"Bathroom") -> 34500 | M10: =SUMIFS(OUT!$F$2:$F$11000,OUT!$H$2:$H$11000,H10,OUT!$D$2:$D$11000,"Out",OUT!$E$2:$E$11000,"Alfa") -> 293800 | N10: =SUMIFS(OUT!$F$2:$F$11000,OUT!$H$2:$H$101007,H10,OUT!$D$2:$D$11000,"Out",OUT!$E$2:$E$11000,"Jajan") -> #VALUE! | O10: =SUMIFS(OUT!$F$2:$F$11000,OUT!$H$2:$H$11000,H10,OUT!$D$2:$D$11000,"Out",OUT!$E$2:$E$11000,"Kitchen") -> 992724 | P10: =SUMIFS(OUT!$F$2:$F$11000,OUT!$H$2:$H$11000,H10,OUT!$D$2:$D$11000,"Out",OUT!$E$2:$E$11000,"Loandry") -> 41600 | Q10: =SUMIFS(OUT!$F$2:$F$11000,OUT!$H$2:$H$11000,H10,OUT!$D$2:$D$11000,"Out",OUT!$E$2:$E$11000,"Mio") -> 249000 | R10: =SUMIFS(OUT!$F$2:$F$11000,OUT!$H$2:$H$11000,H10,OUT!$D$2:$D$11000,"Out",OUT!$E$2:$E$11000,"Sedekah") -> 129000 | S10: =SUMIFS(OUT!$F$2:$F$11000,OUT!$H$2:$H$11000,H10,OUT!$D$2:$D$11000,"Out",OUT!$E$2:$E$11000,"Zela") -> 24100 | T10: =SUMIFS(OUT!$F$2:$F$11000,OUT!$H$2:$H$11000,H10,OUT!$D$2:$D$11000,"Out",OUT!$E$2:$E$11000,"Iqbal") -> 121000
